Workbook
Name BULAN: [1]KASUS10!$I$23:$I$202
Name JKL: [2]parameter!$E$163:$E$164
Name JKW: [2]parameter!$E$190:$E$211
Name kolek: '[3]ASPEK KEU'!$K$46:$K$50
Name PENY: [2]parameter_tier!$E$141:$E$161
Name PKR: [2]parameter!$E$174:$E$177
Name PKS: [2]parameter!$E$184:$E$187
Name S1A: [2]parameter!$E$6:$E$9
Name S1B: [2]parameter!$E$11:$E$12
Name S1C: [2]parameter!$E$14:$E$17
Name S1D: [2]parameter!$E$19:$E$22
Name S2A: [2]parameter!$E$26:$E$29
Name S2B: [2]parameter!$E$31:$E$34
Name S2C: [2]parameter!$E$36:$E$39
Name S3A: [2]parameter!$E$43:$E$46
Name S3B: [2]parameter_tier!$E$48:$E$55
Name S3C: [2]parameter!$E$53:$E$55
Name S3D: [2]parameter!$E$57:$E$60
Name S3E: [2]parameter!$E$62:$E$65
Name S3F: [2]parameter!$E$67:$E$70
Name S3I: [2]parameter!$E$86:$E$89
Name S3J: [2]parameter!$E$91:$E$94
Name S3K: [2]parameter!$E$96:$E$99
Name S4A: [2]parameter!$E$103:$E$106
Name S4D: [2]parameter!$E$118:$E$121
Name S6A: [2]parameter!$E$132:$E$133
Name STA: [2]parameter!$E$180:$E$181
Name TUJ: [2]parameter!$E$159:$E$160

Sheet Informasi Pokok
A2: Kantor (PG) | C2: :
A3: Nomor REGISTER | C3: :
A4: Nomor PROPOSAL | C4: :
A5: Nama AO (M) | C5: : | M5: =" /BPRS-AU/"&M8&"/"&L6 -> /BPRS-AU/V/2025
A6: Tanggal Analisa (M) | C6: : | L6: =YEAR(D6)
A8: 1. INFORMASI POKOK | L8: =MONTH(D6) | M8: =VLOOKUP(L8,L11:M24,2,0)
A10: 1 | B10: Jenis Kategori Nasabah (PG) | F10: =IF(D10="Referral","Nama :","")
A11: =A10+1 | B11: Nama (M) | C11: : | L11: 1 | M11: I
A12: 3 | B12: Jenis Kelamin | C12: :
A13: 4 | B13: Tempat Lahir (M) | C13: : | G13: Tanggal Lahir : | L13: 2 | M13: II
A14: =A13+1 | B14: NIK (M) | C14: : | G14: Usia : | I14: =IF(Parameter!G32<=2,Parameter!E253,Parameter!E254) | L14: 3 | M14: III | N14: 21 - 30 tahun | O14: 21 - 30 tahun
A15: =A14+1 | B15: Alamat (M) | C15: : | L15: 4 | M15: IV | N15: 31 - 40 tahun | O15: 31 - 40 tahun
L16: 5 | M16: V | N16: 41 - 50 tahun | O16: 41 - 50 tahun
D17: Desa/Kelurahan : | H17: Kecamatan : | L17: 6 | M17: VI | N17: 51 - 55 tahun | O17: 51 - 60 tahun
D18: Kab./Kotamadya : | H18: Kode Pos : | L18: 7 | M18: VII
A19: =A18+1 | B19: Telpon Rumah | C19: :
A20: =A15+1 | B20: HP (M) | C20: : | L20: 8 | M20: VIII
A21: =A20+1 | B21: Status Pernikahan (PG) | C21: : | L21: 9 | M21: IX
A22: =A21+1 | B22: Jumlah Tanggungan (PG) | C22: : | L22: 10 | M22: X
A23: =A22+1 | B23: Pendidikan Terakhir (PG) | C23: : | L23: 11 | M23: XI
A24: =A23+1 | B24: Kepemilikan Tempat Tinggal (PG) | C24: : | L24: 12 | M24: XII
A25: =A24+1 | B25: Status Karyawan (PG) | C25: :
A26: =A25+1 | B26: Bidang Usaha Pekerjaan (PG) | C26: :
A27: =A26+1 | B27: Bonafiditas Perusahaan (PG) | C27: :
A28: =A27+1 | B28: Usia Pensiun (O) | C28: : | D28: =IF(Parameter!G32<=2,Parameter!H253,Parameter!H254) | E28: Tahun
A29: =A28+1 | B29: Surat Keterangan Bekerja (PG) | C29: :
A30: =A29+1 | B30: Slip Gaji (PG) | C30: :
A31: =A30+1 | B31: Rekening Gaji (PG) | C31: :
A32: =A31+1 | B32: MoU dengan BPRS Amanah Ummah
A33: =A32+1 | B33: Surat Kuasa Potong Gaji
A34: =A33+1 | B34: Reputasi di Tempat Kerja dan Tempat Tinggal (PG) | C34: :
A35: =A34+1 | B35: Indikator Reputasi di Tempat Kerja dan Tempat Tinggal (M) | C35: :
A36: =A35+1 | B36: Nama Gadis Ibu Kandung (M) | C36: : | L36: Sistem Penj | M36: Konsinyasi / Bagi Hasil
A37: =A36+1 | B37: Nama Pasangan (Suami-Istri) (M) | C37: :
A38: =A37+1 | B38: Tempat/Tanggal Lahir (M) | C38: :
A39: =A38+1 | B39: No. KTP/SIM/Paspor (M) | C39: :
A40: =A39+1 | B40: Pekerjaan Pasangan (Suami-Istri) (M) | C40: :
A41: =A40+1 | B41: Nama Anak Yang Dapat | C41: : | M41: Kredit & Tunai
B42: Dihubungi dan Tidak Serumah (M) | M42: Kredit
A43: =A41+1 | B43: HP (M) | C43: : | M43: Lain-lain
...

Sheet Aspek Non Keuangan
A1: ASPEK NON KEUANGAN
A3: ASPEK MANAJEMEN
A4: a. | B4: Latar Belakang Nasabah (M)
A5: -
A6: -
A10: -
A13: -
A16: b. | B16: Pengalaman Bekerja Nasabah (M) | J16: :
A19: c. | B19: Alamat Perusahaan (M) | J19: :
G23: ASPEK LEGALITAS NASABAH
G24: Nama Instansi/Lembaga | M24: :
G25: Nomor SK | M25: :
G26: Tanggal | M26: :
G27: Atas Nama | M27: :
A29: ASPEK LEGALITAS AGUNAN
A31: - Agunan Tanah/Bangunan
A32: No | B32: Jenis Surat/Dokumen (PG) | G32: No. | H32: Atas Nama (M) | L32: LT2 | M32: LB2 | N32: Nilai Pasar | P32: Nilai | Q32: Os. Pokok | R32: Nilai Bank (O) | V32: Peng ikatan (PG) | X32: Lokasi Agunan (M)
N33: KJPP/Internal (M) | P33: Agunan (%) (M) | Q33: Paripasu (M)
A34: 1 | R34: =(N34*P34)-Q34
A36: =A35+1 | R36: =(N36*P36)-Q36
A37: =A36+1 | R37: =(N37*P37)-Q37
A38: =A37+1 | R38: =(N38*P38)-Q38
A39: =A38+1 | R39: =(N39*P39)-Q39
A40: =A39+1 | R40: =(N40*P40)-Q40
A41: Total (O) | N41: =SUM(N34:O40) | R41: =SUM(R34:U40)
A43: - Agunan Kendaraan Bermotor
A44: No | B44: BPKB-Merek | E44: Type | H44: Thn | I44: Atas Nama | L44: No. BPKB | N44: Nopol | O44: Nilai Pasar | Q44: Nilai Agunan | R44: Os. Pokok | V44: Nilai Bank (O) | Z44: Pengikatan (PG)
O45: KJPP/Internal (M) | Q45: (%) (M) | R45: Paripasu (M)
A47: 2 | Q47: 0.8 | V47: =(O47*Q47)-R47
A48: 3 | Q48: 0.8 | V48: =(O48*Q48)-R48
A49: 4 | Q49: 0.8 | V49: =(O49*Q49)-R49
A50: 5 | Q50: 0.8 | V50: =(O50*Q50)-R50
A51: Total (O) | O51: =SUM(O46:P50) | R51: =SUM(R46:U50) | V51: =SUM(V46:Y50)
A53: - Surat Berharga/Logam Mulia
A54: No | B54: Jenis | E54: Nomor | H54: Atas Nama | L54: Nominal (M) | O54: Nilai Agunan (%) (M) | Q54: Os. Pokok | S54: Nilai Bank (O)
Q55: Paripasu (M)
A56: 1 | O56: 1 | S56: =(L56*O56)-Q56
A57: 2 | O57: 1 | S57: =(L57*O57)-Q57
A58: 3 | O58: 1 | S58: =(L58*O58)-Q58
A59: 4 | O59: 1 | S59: =(L59*O59)-Q59
...

Sheet Aspek Keuangan
A1: ANALISA KEUANGAN
A3: 1. PENDAPATAN TETAP
C5: Gaji Bulanan (THP) (M) | L5: :
C6: Uang Lembur (M) | L6: :
C7: Pendapatan Tetap Lainnya (M) | L7: :
C8: Total Pendapatan Tetap (O) | L8: : | M8: =SUM(M5:O7)
C10: Persentase Potongan Gaji (%)(PG) | L10: : | AE10: 0.3
C12: RPC/NPM | L12: : | M12: =M8*M10
A14: 2. PENDAPATAN TIDAK TETAP
B16: PENJUALAN
B18: No | C18: Nama Barang | H18: BULAN I | O18: BULAN II | W18: BULAN III
H19: Hari | I19: Omset/Hari | L19: Omset/Bulan | O19: Hari | P19: Omset/Hari | S19: Omzet/Bulan | W19: Hari | X19: Omset/Hari | Z19: Omset/Bulan (O)
B20: 1 | L20: =H20*I20 | S20: =O20*P20 | Z20: =X20*W20
B21: 2 | L21: =H21*I21 | S21: =O21*P21 | Z21: =X21*W21
B22: Total | I22: =SUM(I20:K21) | L22: =SUM(L20:N21) | P22: =SUM(P20:R21) | S22: =SUM(S20:U21) | X22: =SUM(X20:Y21) | Z22: =SUM(Z20:AB21)
B26: No | C26: Nama Barang | H26: RATA-RATA | O26: HPP
H27: Hari | I27: Omzet/Hari | L27: Omzet/Bulan | O27: % | P27: Nominal
B28: 1 | C28: =C20 | H28: =(H20+O20+W20)/3 | I28: =(I20+P20+X20)/3 | L28: =(L20+S20+Z20)/3 | P28: =L28*O28
B29: 2 | C29: =C21 | H29: =(H21+O21+W21)/3 | I29: =(I21+P21+X21)/3 | L29: =(L21+S21+Z21)/3 | P29: =L29*O29
B30: Total | H30: =AVERAGE(H28:H29) | I30: =SUM(I28:K29) | L30: =SUM(L28:N29) | O30: =AVERAGE(O28:O29) | P30: =SUM(P28:S29)
B32: Rata-Rata Penjualan 3 Bulan Terakhir | M32: : | N32: =(L22+S22+Z22)/3
A34: 3. BIAYA TENAGA KERJA
C36: Jumlah Tenaga Kerja Yang Digaji Harian (M) | L36: :
C37: Besarnya Upah Per Hari Per Orang (M) | L37: :
C39: Jumlah Tenaga Kerja Yang Digaji Mingguan (M) | L39: :
C40: Besarnya Upah Per Minggu Per Orang (M) | L40: :
C42: Jumlah Tenaga Kerja Yang Digaji Bulanan (M) | L42: :
C43: Besarnya Upah Per Bulan Per Orang (M) | L43: : | AN43: : | AO43: 0.2
C45: TOTAL BIAYA TENAGA KERJA (O) | L45: : | M45: =(M36*M37*30)+(M39*M40*4)+(M42*M43)
A47: 4. BIAYA USAHA
C49: Biaya LISTRIK & Air Tempat Usaha (M) | L49: :
C50: Biaya Perawatan (M) | L50: :
C51: Biaya SEWA Tempat Usaha (M) | L51: :
C52: Biaya Transportasi & Perawatan (M) | L52: :
C53: Biaya HANDPHONE Usaha (M) | L53: :
C55: TOTAL BIAYA USAHA (O) | L55: : | M55: =SUM(M49:O54)
A57: 4. LABA RUGI USAHA
C59: Penjualan | L59: : | M59: =N32 | AE59: 0.3
C60: HPP | L60: : | M60: =P30 | AE60: 0.35
C61: Laba Kotor | L61: : | M61: =M59-M60
...

Sheet AKTIVITAS USAHA
A1: URAIAN AKTIVITAS USAHA DEBITUR/CALON DEBITUR
A3: ASPEK PEMASARAN
A4: A. | B4: TINGKAT PERMINTAAN
B5: Performance Indicator | H5: Uraian Singkat
B6: Ukuran target pasar (market size) | H6: Tingkat konsumsi tinggi, daya beli tinggi
B8: Luas area geografis target pasar. | H8: Regional
B10: Pola/sifat permintaan target pasar | H10: stabil
B12: Pertumbuhan permintaan target pasar | H12: Diperkirakan 0% s/d 5%
B14: Pangsa Pasar Perusahaan | H14: Diperkirakan 20 besar
B15: Diversifikasi segmen pasar perusahaan | H15: 5 segmen atau lebih
B17: Realisasi penjualan dibanding target | H17: Penjualan kurang dari 50% target
A20: B. | B20: KUALITAS PRODUK ATAU JASA
B21: Performance Indicator | H21: Uraian Singkat
B22: Kualitas produk/jasa | H22: ◊ | I22: Reliabilitas/Keandalan
H26: ◊ | I26: Jaminan Kepastian
H30: ◊ | I30: Pelayanan
I31: Produk yang ditawarkan cukup dikenal oleh masyarakat, dan tetap digunakan di setiap waktu.
H34: ◊ | I34: Empati
I35: Kebutuhan pelanggan terhadap produk tsb tetap dipertahankan. Apabila pelanggan mengeluh, pemohon mengantisipasi dengan cepat. Hal ini terlihat banyaknya pelanggan pemohon.
H38: ◊ | I38: Responsif
I39: Pemohon mampu memberikan pelayanan dan pengiriman yang cepat kepada pelanggannya. Hal ini terlihat dari jumlah alat transportasi yang digunakan oleh pemohon.
B43: Tingkat harga produk/jasa | H43: Di bawah harga pasar.
B45: Rentang jenis produk (diversifikasi produk)
B49: Kekuatan merk (brand image) | H49: Untuk produk yang ditawarkan oleh pemohon beberapa produk telah cukup dikenal oleh para pelanggannya. Hal ini terlihat dari jumlah penjualan setiap harinya.
B53: Inovasi produk/jasa
B57: Jaringan distribusi | H57: Di atas 15 cabang/ outlet/agen/sales forces
B59: Syarat-syarat penjualan | H59: Syarat-syarat penjualan yang dilakukan pemohon antara lain:
I63: - | J63: Pemohon lebih mengutamakan pembayaran tunai
I64: - | J64: Untuk pembayaran kredit diperbolehkan dengan masa 1-2 hari
I65: - | J65: Penjualan ditargetkan sebanyak +/-50%
I66: -
A68: C. | B68: KONSENTRASI PELANGGAN
B69: Performance Indicator | H69: Uraian Singkat
B70: Proporsi penjualan per pelanggan | H70: 4 pelanggan menguasai 15% penjualan atau lebih
B72: Kualitas hubungan dengan pelanggan | H72: Hubungan antara pemohon dengan para pelanggannya telah terjalin baik hal ini terlihat antara lain:
I75: - | J75: Lamanya hubungan dengan pelanggan
I76: - | J76: Track record penyelesaian hak-kewajiban pelanggan
I77: - | J77: Untuk di wilayah tsb pemohon telah dikenal baik oleh para pelanggannya
B79: Daya tawar pelanggan | H79: Tawar menawar antara pelanggan dengan pemohon cukup baik. Hal ini terlihat dari beberapa faktor antara lain:
I82: - | J82: Planggan mengutamakan harga yang murah, hingga pelanggan
...

Sheet Rekening Koran & Aset
A1: BANK (M): | D1: Currency (M): | E1: IDR | G1: ='Informasi Pokok'!D6
A2: Nomor Rekening (M): | D2: Saldo Awal (M):
A3: Atas Nama (M): | C3: ='Informasi Pokok'!D11
A5: Bulan | B5: Mutasi Debet | C5: Mutasi Kredit | D5: Saldo | E5: Bulan | F5: Mutasi Debet | G5: Mutasi Kredit | H5: Saldo | I5: Bulan | J5: Mutasi Debet | K5: Mutasi Kredit | L5: Saldo
D6: =E2 | E6: =IF(A6="","",DATE(YEAR(A6),MONTH(A6)+1,DAY(A6))) | H6: =D53 | I6: =IF(E6="","",DATE(YEAR(E6),MONTH(E6)+1,DAY(E6))) | L6: =H53 | M6: Bulan | N6: FQ | O6: Debet | P6: Rata2 Transaksi | Q6: FQ | R6: Kredit | S6: Rata2 Transaksi | T6: Saldo Akhir
A7: =$A$6 | D7: =D6-B7+C7 | E7: =$E$6 | H7: =H6-F7+G7 | I7: =$I$6 | L7: =L6-J7+K7 | M7: =A6 | N7: =B57 | O7: =B55 | P7: =B56 | Q7: =C57 | R7: =C55 | S7: =C56 | T7: =D53
A8: =$A$6 | D8: =D7-B8+C8 | E8: =$E$6 | H8: =H7-F8+G8 | I8: =$I$6 | L8: =L7-J8+K8 | M8: =E6 | N8: =F57 | O8: =F55 | P8: =F56 | Q8: =G57 | R8: =G55 | S8: =G56 | T8: =H53
A9: =$A$6 | D9: =D8-B9+C9 | E9: =$E$6 | H9: =H8-F9+G9 | I9: =$I$6 | L9: =L8-J9+K9 | M9: =I6 | N9: =J57 | O9: =J55 | P9: =J56 | Q9: =K57 | R9: =K55 | S9: =K56 | T9: =L53
A10: =$A$6 | D10: =D9-B10+C10 | E10: =$E$6 | H10: =H9-F10+G10 | I10: =$I$6 | L10: =L9-J10+K10 | M10: Rata-rata | N10: =AVERAGE(N7:N9) | O10: =AVERAGE(O7:O9) | P10: =AVERAGE(P7:P9) | Q10: =AVERAGE(Q7:Q9) | R10: =AVERAGE(R7:R9) | S10: =AVERAGE(S7:S9) | T10: =AVERAGE(T7:T9)
A11: =$A$6 | D11: =D10-B11+C11 | E11: =$E$6 | H11: =H10-F11+G11 | I11: =$I$6 | L11: =L10-J11+K11
A12: =$A$6 | D12: =D11-B12+C12 | E12: =$E$6 | H12: =H11-F12+G12 | I12: =$I$6 | L12: =L11-J12+K12
A13: =$A$6 | D13: =D12-B13+C13 | E13: =$E$6 | H13: =H12-F13+G13 | I13: =$I$6 | L13: =L12-J13+K13
A14: =$A$6 | D14: =D13-B14+C14 | E14: =$E$6 | H14: =H13-F14+G14 | I14: =$I$6 | L14: =L13-J14+K14
A15: =$A$6 | D15: =D14-B15+C15 | E15: =$E$6 | H15: =H14-F15+G15 | I15: =$I$6 | L15: =L14-J15+K15
A16: =$A$6 | D16: =D15-B16+C16 | E16: =$E$6 | H16: =H15-F16+G16 | I16: =$I$6 | L16: =L15-J16+K16
A17: =$A$6 | D17: =D16-B17+C17 | E17: =$E$6 | H17: =H16-F17+G17 | I17: =$I$6 | L17: =L16-J17+K17
A18: =$A$6 | D18: =D17-B18+C18 | E18: =$E$6 | H18: =H17-F18+G18 | I18: =$I$6 | L18: =L17-J18+K18
A19: =$A$6 | D19: =D18-B19+C19 | E19: =$E$6 | H19: =H18-F19+G19 | I19: =$I$6 | L19: =L18-J19+K19
A20: =$A$6 | D20: =D19-B20+C20 | E20: =$E$6 | H20: =H19-F20+G20 | I20: =$I$6 | L20: =L19-J20+K20
A21: =$A$6 | D21: =D20-B21+C21 | E21: =$E$6 | H21: =H20-F21+G21 | I21: =$I$6 | L21: =L20-J21+K21
A22: =$A$6 | D22: =D21-B22+C22 | E22: =$E$6 | H22: =H21-F22+G22 | I22: =$I$6 | L22: =L21-J22+K22
... A53: =$A$6 | D53: =D52-B53+C53 | E53: =$E$6 | H53: =H52-F53+G53 | I53: =$I$6 | L53: =L52-J53+K53
A55: Total | B55: =SUM(B7:B53) | C55: =SUM(C7:C53) | E55: Total | F55: =SUM(F7:F53) | G55: =SUM(G7:G53) | I55: Total | J55: =SUM(J7:J53) | K55: =SUM(K7:K53)
A56: Average | B56: =AVERAGE(B7:B53) | C56: =AVERAGE(C7:C53) | E56: Average | F56: =AVERAGE(F7:F53) | G56: =AVERAGE(G7:G53) | I56: Average | J56: =AVERAGE(J7:J53) | K56: =AVERAGE(K7:K53)
A57: FQ | B57: =COUNT(B7:B53) | C57: =COUNT(C7:C53) | F57: =COUNT(F7:F53) | G57: =COUNT(G7:G53) | J57: =COUNT(J7:J53) | K57: =COUNT(K7:K53)
B60: ASSET YANG DIMILIKI
B62: Jenis Asset (M) | D62: Saldo Bank | F62: Jenis Asset (M)
B63: Jumlah (O) | D63: =T9 | F63: Jumlah (M)
B64: Nama Bank (O) | D64: =C1 | F64: Tahun Perolehan (M)
F65: Nilai Taksasi Bank (M)
B67: Jenis Asset (M) | F67: Jenis Asset (M)
B68: Jumlah (M) | F68: Jumlah (M)
B69: Tahun Perolehan (M) | F69: Tahun Perolehan (M)
B70: Nilai Taksasi Bank (M) | F70: Nilai Taksasi Bank (M)
B72: Total Asset (O) | E72: : | F72: =D63+H65+D70+H70
A75: VERIFIKASI
F77: Mengetahui | J77: Pengusul,
J81: ='Informasi Pokok'!D5
F82: Koord Marketing | J82: Account Officer
A84: PETUGAS VERIFIKASI | G84: CATATAN
...

Sheet Usulan Pembiayaan
A2: MEMORANDUM USULAN PEMBIAYAAN | AA2: kdprd | AB2: prd
B3: Nomor MUP | F3: : | G3: =" "&'Informasi Pokok'!D3 -> 021/Reg/BS-AR/V/2025 | AA3: 10 | AB3: Murabahah | AC3: Harga Pokok | AD3: Margin | AE3: Harga Jual | AF3: Harga Pokok Barang | AG3: Urbun/Uang Muka I | AH3: Urbun/Uang Muka II | AI3: ---∞∞∞∞∞¶¶¶¶¶∞∞∞∞∞--- | AJ3: Pembiayaan Bank | AK3: Angsuran Margin/Bulan | AL3: Expected Return/Bulan | AM3: Angsuran Pokok/Bulan | AN3: Total Angsuran/Bulan | AO3: =$J$49-$J$50-$J$51 | AP3: Surplus/Minus Cashflow
B4: Tanggal Usulan | F4: : | G4: =TODAY() | AA4: 11 | AB4: PKE | AC4: Harga Pokok | AD4: Margin | AE4: Harga Jual | AF4: Harga Pokok Barang | AG4: Urbun/Uang Muka I | AH4: Urbun/Uang Muka II | AI4: ---∞∞∞∞∞¶¶¶¶¶∞∞∞∞∞--- | AJ4: Pembiayaan Bank | AK4: Angsuran Margin/Bulan | AL4: Expected Return/Bulan | AM4: Angsuran Pokok/Bulan | AN4: Total Angsuran/Bulan | AO4: =$J$49-$J$50-$J$51 | AP4: Surplus/Minus Cashflow
B5: Dari | F5: : | G5: Account Officer | AA5: 20 | AB5: Istishna | AC5: Harga Pokok | AD5: Margin | AE5: Harga Jual | AF5: Harga Pokok Barang | AG5: Urbun/Uang Muka I | AH5: Urbun/Uang Muka II | AI5: ---∞∞∞∞∞¶¶¶¶¶∞∞∞∞∞--- | AJ5: Pembiayaan Bank | AK5: Angsuran Margin/Bulan | AL5: Expected Return/Bulan | AM5: Angsuran Pokok/Bulan | AN5: Total Angsuran/Bulan | AO5: =$J$49-$J$50-$J$51 | AP5: Surplus/Minus Cashflow
B6: Kepada | F6: : | G6: Komite Pemutus Pembiayaan (KMPP) | AA6: 30 | AB6: Salam | AC6: Harga Pokok | AD6: Margin | AE6: Harga Jual | AF6: Harga Pokok Barang | AG6: Urbun/Uang Muka I | AH6: Urbun/Uang Muka II | AI6: ---∞∞∞∞∞¶¶¶¶¶∞∞∞∞∞--- | AJ6: Pembiayaan Bank | AK6: Angsuran Margin/Bulan | AL6: Expected Return/Bulan | AM6: Angsuran Pokok/Bulan | AN6: Total Angsuran/Bulan | AO6: =$J$49-$J$50-$J$51 | AP6: Surplus/Minus Cashflow
B7: Perihal | F7: : | G7: ="Permohonan Pembiayaan atas nama "&N14 | AA7: 50 | AB7: Ijarah | AC7: Harga Pokok Sewa | AD7: Ujroh | AE7: Harga Jual Sewa | AF7: Harga Pokok sewa | AG7: Urbun/Uang Muka I | AH7: Urbun/Uang Muka II | AI7: ---∞∞∞∞∞¶¶¶¶¶∞∞∞∞∞--- | AJ7: Pembiayaan Bank | AK7: Ujroh Sewa/Bulan | AL7: Ujroh Sewa (Setara)/Bulan | AM7: Angsuran Pokok Sewa/Bulan | AN7: Total Angsuran Sewa/Bln | AO7: =$J$49-$J$50-$J$51 | AP7: Surplus/Minus Cashflow
AA8: 51 | AB8: Ijarah Multijasa | AC8: Harga Pokok Sewa | AD8: Ujroh | AE8: Harga Jual Sewa | AF8: Harga Pokok sewa | AG8: Urbun/Uang Muka I | AH8: Urbun/Uang Muka II | AI8: ---∞∞∞∞∞¶¶¶¶¶∞∞∞∞∞--- | AJ8: Pembiayaan Bank | AK8: Ujroh Sewa/Bulan | AL8: Ujroh Sewa (Setara)/Bulan | AM8: Angsuran Pokok Sewa/Bulan | AN8: Total Angsuran Sewa/Bln | AO8: =$J$49-$J$50-$J$51 | AP8: Surplus/Minus Cashflow
B9: Assalamu'alaikum wr.wb. | AA9: 70 | AB9: Mudharabah | AC9: Pokok | AD9: Proyeksi Bagi Hasil | AE9: Total | AF9: Nilai Proyek | AG9: Modal Nasabah | AH9: Modal Bank | AI9: ---∞∞∞∞∞¶¶¶¶¶∞∞∞∞∞--- | AJ9: Pembiayaan Bank | AK9: Proyeksi Bagi Hasil/Bulan | AL9: Expected Return/Bulan | AM9: Proyeksi Angsuran Pokok/Bulan | AN9: Proyeksi Angsuran Pokok&Bagas/Bln | AO9: =$J$49-$J$50 | AP9: Proyeksi Surplus/Minus Cashflow
B10: ="Kami sampaikan Memorandum Usulan Pembiayaan atas nama "&N14&" dengan hal-hal sebagai berikut:" | AA10: 60 | AB10: Musyarakah | AC10: Pokok | AD10: Proyeksi Bagi Hasil | AE10: Total | AF10: Nilai Proyek | AG10: Modal Nasabah | AH10: Modal Bank | AI10: ---∞∞∞∞∞¶¶¶¶¶∞∞∞∞∞--- | AJ10: Pembiayaan Bank | AK10: Proyeksi Bagi Hasil/Bulan | AL10: Expected Return/Bulan | AM10: Proyeksi Angsuran Pokok/Bulan | AN10: Proyeksi Angsuran Pokok&Bagas/Bln | AO10: =$J$49-$J$50 | AP10: Proyeksi Surplus/Minus Cashflow
AA11: 65 | AB11: MMQ RS | AC11: Pokok (Hishah) | AD11: Bagi Hasil Atas Sewa | AE11: Harga Jual Sewa | AF11: Harga Pasar Aset | AG11: Harga Aset yang Dibeli Bank dari Nas. | AH11: Kepemilikan Aset Bank (Hishah) | AI11: Kepemilikan Aset Nasabah (Hishah) | AJ11: Harga Aset yang Disewa Nasabah | AK11: Ujroh Sewa/Bulan | AL11: Ujroh Sewa (Setara)/Bulan | AM11: Penebusan Aset/Hishah Oleh Nas. | AN11: Total Angsuran Sewa/Bln | AO11: =J49-J52 | AP11: Surplus/Minus Cashflow
A12: PERMOHONAN YANG DIAJUKAN | AA12: 52 | AB12: IMBT RS | AC12: Harga Pokok Sewa | AD12: Ujroh | AE12: Harga Jual Sewa | AF12: Harga Pasar Aset | AG12: Harga Aset yang Dibeli Bank dari Nas. | AH12: ---∞∞∞∞∞¶¶¶¶¶∞∞∞∞∞--- | AI12: ---∞∞∞∞∞¶¶¶¶¶∞∞∞∞∞--- | AJ12: Harga Aset yang Disewa Nasabah | AK12: Ujroh Sewa/Bulan | AL12: Ujroh Sewa (Setara)/Bulan | AM12: Angsuran Pokok Sewa/Bulan | AN12: Total Angsuran Sewa/Bln | AO12: =J50 | AP12: Surplus/Minus Cashflow
AA13: 40 | AB13: Qardh | AC13: Pokok | AD13: ---∞∞∞∞∞¶¶¶¶¶∞∞∞∞∞--- | AE13: ---∞∞∞∞∞¶¶¶¶¶∞∞∞∞∞--- | AF13: ---∞∞∞∞∞¶¶¶¶¶∞∞∞∞∞--- | AG13: ---∞∞∞∞∞¶¶¶¶¶∞∞∞∞∞--- | AH13: ---∞∞∞∞∞¶¶¶¶¶∞∞∞∞∞--- | AI13: ---∞∞∞∞∞¶¶¶¶¶∞∞∞∞∞--- | AJ13: Pembiayaan Bank | AK13: - | AL13: - | AM13: Angsuran Pokok | AN13: Total Angsuran/Bulan | AO13: =J49 | AP13: Surplus/Minus Cashflow
A14: 1 | B14: Nama Pemohon | L14: : | N14: ='Informasi Pokok'!D11
A15: 2 | B15: Akad Pembiayaan | L15: : | N15: ='Informasi Pokok'!D58
A16: 3 | B16: Jenis Penggunaan | L16: : | N16: ='Informasi Pokok'!D60
A17: 4 | B17: Jumlah Permohonan | L17: : | N17: ='Informasi Pokok'!D55
A18: 5 | B18: Expected Return/Bulan | L18: : | N18: ='Informasi Pokok'!D57 | R18: ='Informasi Pokok'!E57
A19: 6 | B19: Jangka Waktu | L19: : | N19: ='Informasi Pokok'!D56 | R19: Bulan | AB19: ='Informasi Pokok'!D58 | AC19: =VLOOKUP($AB$19,$AB$3:$AO$14,2,0) | AD19: =VLOOKUP($AB$19,$AB$3:$AO$14,3,0) | AE19: =VLOOKUP($AB$19,$AB$3:$AO$14,4,0) | AF19: =VLOOKUP($AB$19,$AB$3:$AO$14,5,0) | AG19: =VLOOKUP($AB$19,$AB$3:$AO$14,6,0) | AH19: =VLOOKUP($AB$19,$AB$3:$AO$14,7,0) | AI19: =VLOOKUP($AB$19,$AB$3:$AO$14,8,0) | AJ19: =VLOOKUP($AB$19,$AB$3:$AO$14,9,0) | AK19: =VLOOKUP($AB$19,$AB$3:$AO$14,10,0) | AL19: =VLOOKUP($AB$19,$AB$3:$AO$14,11,0) | AM19: =VLOOKUP($AB$19,$AB$3:$AO$14,12,0) | AN19: =VLOOKUP($AB$19,$AB$3:$AO$14,13,0) | AO19: =VLOOKUP($AB$19,$AB$3:$AO$14,14,0) | AP19: =VLOOKUP($AB$19,$AB$3:$AP$14,15,0)
A20: 7 | B20: Angsuran Perbulan | L20: : | N20: =IF(R18="Flat",AB20,AC20) | AB20: =(N17*N18*N19+N17)/N19 | AC20: =PMT(N18,N19,-N17)
A22: ANALISA KEUANGAN | AC22: 1.75 | AD22: 2
A24: 1 | B24: RPC Pendapatan Tetap | L24: : | N24: ='Aspek Keuangan'!M12
A25: 2 | B25: RPC Pendapatan Tidak Tetap | L25: : | N25: ='Aspek Keuangan'!M69
A26: 3 | B26: Kewajiban Kepada Pihak Lain | L26: : | N26: ='Aspek Keuangan'!N81+'Aspek Keuangan'!N93
A27: 4 | B27: Potensi Besarnya Angsuran | L27: : | N27: =(N24+N25)-N26
A29: ANALISA PLAFOND
A31: Plafond Maksimal | AA31: 1 | AB31: min | AC31: mid
I32: =AC19 | P32: : | Q32: =(Q34/(100%+(J54*J55))) | AA32: 0.3 | AB32: RPC <3.33 | AC32: RPC 3.33 sd. 4.50 | AD32: RPC >4.50 sd. 6.50 | AE32: RPC >6.50
I33: =AD19 | P33: : | Q33: =Q34-Q32 | AA33: 0.35 | AB33: RPC <2.86 | AC33: RPC 2.86 sd. 4.25 | AD33: RPC >4.25 sd. 6.50 | AE33: RPC >6.50
I34: =AE19 | P34: : | Q34: =N27*J54 | AA34: 0.4 | AB34: RPC <2.50 | AC34: RPC 2.50 sd. 4 | AD34: RPC >4 sd. 6 | AE34: RPC >6
I35: Angsuran/Bulan I | P35: : | Q35: =Q34/J54 | AA35: =N25 | AB35: =AA31/AA35
A37: Plafond yang Diajukan | AA37: =B74 | AB37: =VLOOKUP(AA35,AA31:AE34,3,0)
I38: =AC19 | P38: : | Q38: =N17
I39: =AD19 | P39: : | Q39: =Q38*N18*N19 | AA39: 0.4 | AB39: =IF($AA$37<2.5,"RPC <2.50",IF(AND($AA$37>=2.5,$AA$37<=4),"RPC 2.50 sd. 4",IF(AND($AA$37>4,$AA$37<=6),"RPC >4 sd. 6",IF($AA$37>6,"RPC >6")))) | AC39: =IF($AA$37<2.5,AB34,IF(AND($AA$37>=2.5,$AA$37<=4),AC34,IF(AND($AA$37>4,$AA$37<=6),AD34,IF($AA$37>6,AE34))))
I40: =AE19 | P40: : | Q40: =SUM(Q38:S39) | AA40: 0.35 | AB40: =IF($AA$37<2.86,"RPC <2.86",IF(AND($AA$37>=2.86,$AA$37<=4.25),"RPC 2.86 sd. 4.25",IF(AND($AA$37>4.25,$AA$37<=6.5),"RPC >4.25 sd. 6.50",IF($AA$37>6.5,"RPC >6.50")))) | AC40: =IF($AA$37<2.86,AB33,IF(AND($AA$37>=2.86,$AA$37<=4.25),AC33,IF(AND($AA$37>4.25,$AA$37<=6.5),AD33,IF($AA$37>6.5,AE33))))
I41: Angsuran/Bulan II | P41: : | Q41: =Q40/N19 | AA41: 0.3 | AB41: =IF($AA$37<3.33,"RPC <3.33",IF(AND($AA$37>=3.33,$AA$37<=4.5),"RPC 3.33 sd. 4.50",IF(AND($AA$37>4.5,$AA$37<=6.5),"RPC >4 sd. 6.50",IF($AA$37>6.5,"RPC >6.50")))) | AC41: =IF($AA$37<3.33,AB32,IF(AND($AA$37>=3.33,$AA$37<=4.5),AC32,IF(AND($AA$37>4.5,$AA$37<=6.5),AD32,IF($AA$37>6.5,AE32))))
I42: Surplus Cashflow | P42: : | Q42: =N27-Q41
AF45: =IF(AE58=0,0,AE56)
A47: USULAN PEMBIAYAAN
N48: =IF(Parameter!G32<=2,'Usulan Pembiayaan'!AC48,'Usulan Pembiayaan'!AC49) | AA48: =Parameter!H253 | AB48: =AA48*12 | AC48: =IF(J54>AB48,"Jangka Waktu Melebihi Usia Pensiun","")
B49: =$AF$19 | I49: : | AA49: =Parameter!H254 | AB49: =AA49*12 | AC49: =IF(J54>AB49,"Jangka Waktu > Usia Pensiun","")
...

Sheet K Modal
B2: PERPUTARAN MODAL KERJA
Y3: Kebutuhan Modal Kerja | AB3: Kebutuhan Modal Kerja Berdasakan Perputaran Usaha
B4: Perputaran Kas | H4: : | I4: Δ | J4: Penjualan | M4: = | N4: ='Usulan Pembiayaan'!N24:Q24 | S4: = | T4: =N4/N5 | V4: kali | Y4: Tranding Asset | Z4: =+N17+N11 | AB4: Perputaran Persediaan | AC4: =+N17*30/N4
J5: Kas | N5: ='Aspek Keuangan'!#REF! | Y5: SF | Z5: ='Aspek Keuangan'!#REF! | AB5: Perputaran Piutang | AC5: =+N11*30/N4
Y6: Kebutuhan Modal | Z6: =+Z4-Z5 | AB6: Perputaran Utang | AC6: =('Aspek Keuangan'!#REF!+200000000)*30/N4
I7: Δ | J7: HARI | L7: = | M7: 30 | O7: = | P7: =M7/M8 | R7: hari | Y7: PM 15% | Z7: ='Aspek Keuangan'!#REF!*Z6 | AB7: NTC | AC7: =+(AC4+AC5)-AC6
M8: =T4 | Y8: Kebutuhan Modal Kerja Netto | Z8: =+Z6-Z7 | AB8: Kebutuhan Modal Kerja Netto | AC8: =((1-(100%-85%))*((N4*AC7)/30))
Y9: 1.1 | Z9: =Z8*Y9 | AC9: =S34-AC8
B10: Perputaran Piutang | H10: : | I10: Δ | J10: Penjualan | M10: = | N10: =N4 | S10: = | T10: =N10/N11 | V10: kali | AC10: =AC9/S34
J11: Piutang | N11: ='Aspek Keuangan'!#REF!
I13: Δ | J13: HARI | L13: = | M13: 30 | O13: = | P13: =M13/M14 | R13: hari
M14: =T10 | Y14: =N4*85%
B16: Perputaran Persediaan | H16: : | I16: Δ | J16: HPP | M16: = | N16: =Y14 | S16: = | T16: =N16/N17 | V16: kali
J17: Persediaan | N17: ='Aspek Keuangan'!#REF!
I19: Δ | J19: HARI | L19: = | M19: 30 | O19: = | P19: =M19/M20 | R19: hari
M20: =T16
B23: Proyeksi Kas | G23: : | H23: =P7 | J23: X | K23: =N4 | O23: X | P23: 1 | R23: = | S23: =(H23*K23/H24)*P23
H24: 30
B26: Proyeksi Piutang | G26: : | H26: =P13 | J26: X | K26: =N10 | O26: X | P26: 1.2 | R26: = | S26: =(K26*H26/H27)*P26
H27: 30
B29: Proyeksi Persediaan | G29: : | H29: =P19 | J29: X | K29: =N16 | O29: X | P29: 1.2 | R29: = | S29: =(K29*H29/H30)*P29
H30: 30
B32: Jumlah Proyeksi Modal kerja | S32: =S23+S26+S29
B34: Modal Kerja Bersih | S34: =N17+N11+N5 | W34: (-)
S35: =S32-S34
B36: Kebutuhan Kredit
B38: Hutang Dagang
B40: Hutang Bank | L40: (+)
S41: =H38+H40 | W41: (+)
B43: Total Kebutuhan Kredit | S43: =S35+S41

Sheet Komite Kredit
A1: KEPUTUSAN KREDIT
R3: Tanggal | U3: =TODAY()
A4: A. | B4: DATA DEBITUR
B5: - | C5: Nama Debitur | I5: : | J5: ='Informasi Pokok'!D11
B6: - | C6: Alamat Debitur | I6: : | J6: ='Informasi Pokok'!D15
B7: - | C7: Pekerjaan | I7: :
A9: B. | B9: FASILITAS KREDIT
B10: - | C10: ='Usulan Pembiayaan'!B15 | I10: : | J10: ='Usulan Pembiayaan'!N15 | O10: - | P10: Gol Debitur | U10: : | V10: 875
B11: - | C11: ='Usulan Pembiayaan'!#REF! | I11: : | J11: ='Usulan Pembiayaan'!#REF! | O11: - | P11: Sifat kredit | U11: : | V11: 3
B12: - | C12: ='Usulan Pembiayaan'!#REF! | I12: : | J12: ='Usulan Pembiayaan'!#REF! | O12: - | P12: Jenis Penggunaan | U12: : | V12: 10
B13: - | C13: ='Usulan Pembiayaan'!#REF! | I13: : | J13: ='Usulan Pembiayaan'!#REF! | O13: - | P13: Sektor Ekonomi | U13: : | V13: 1007
B14: - | C14: ='Usulan Pembiayaan'!#REF! | I14: : | J14: ='Usulan Pembiayaan'!#REF! | O14: - | P14: Hub. dengan Bank | U14: : | V14: 02
B15: - | C15: ='Usulan Pembiayaan'!#REF! | I15: : | J15: ='Usulan Pembiayaan'!#REF!
A17: C. | B17: JAMINAN
B18: No | C18: Jenis Agunan | K18: Pengikatan | N18: Nilai Pasar | R18: % | S18: Nilai | W18: Nilai HT
B19: 1 | K19: ='Aspek Non Keuangan'!#REF! | N19: ='Aspek Non Keuangan'!#REF! | R19: 0.8 | S19: ='Aspek Non Keuangan'!#REF! | W19: ='Aspek Non Keuangan'!#REF!
B20: 2 | K20: ='Aspek Non Keuangan'!#REF! | N20: ='Aspek Non Keuangan'!#REF! | R20: 0.6 | S20: ='Aspek Non Keuangan'!#REF! | W20: ='Aspek Non Keuangan'!#REF!
B21: 3 | K21: ='Aspek Non Keuangan'!#REF! | N21: ='Aspek Non Keuangan'!#REF! | R21: 0.6 | S21: ='Aspek Non Keuangan'!#REF! | W21: ='Aspek Non Keuangan'!#REF!
B22: Total | N22: =SUM(N19:Q21) | S22: =SUM(S19:V21) | W22: =SUM(W19:Z21)
B23: Keterangan :
A27: D. | B27: PENGIKATAN
B28: - | C28: Pengikatan Kredit diikat Secara | L28: : | M28: Notaril
B29: - | C29: Daftar Asuransi Jiwa | L29: : | M29: Didaftarkan
B30: - | C30: Agunan Kendaraan | L30: : | M30: Diasuransikan (minimal TLO)
A32: Demikian, Keputusan Komite Kredit ini dibuat sebagai pedoman keputusan pemberian kredit.
A34: Pemutus Kredit Non Limit
A35: Area Manager
AC39: 3241250
A40: Pemutus Kredit Non Limit | AC40: 874500
A41: Direktur Operasional | AC41: =+AC39-AC40
AC42: 955556 | AD42: =+AC41/AC42
AC43: =+AC41-AC42
A46: Pemutus Kredit Pemegang Limit
A47: Direktur Utama

Sheet Keputusan Pembiayaan
A2: MEMO KEPUTUSAN PEMBIAYAAN
A6: PERMOHONAN YANG DIAJUKAN
A8: 1 | B8: No. MUP | L8: : | N8: =" "&'Informasi Pokok'!D3 -> 021/Reg/BS-AR/V/2025
A9: 2 | B9: Kantor | L9: : | N9: ='Informasi Pokok'!D2
A10: 3 | B10: Nama Account Officer | L10: : | N10: ='Informasi Pokok'!D5
A11: 4 | B11: Nama Pemohon | L11: : | N11: ='Informasi Pokok'!D11
A12: 5 | B12: Akad Pembiayaan | L12: : | N12: ='Informasi Pokok'!D58
A13: 6 | B13: Jenis Penggunaan | L13: : | N13: ='Informasi Pokok'!D60
A14: 7 | B14: Jumlah Permohonan | L14: : | N14: ='Informasi Pokok'!D55
A15: 8 | B15: Jangka Waktu | L15: : | N15: ='Usulan Pembiayaan'!N19&" Bulan"
A16: 9 | B16: Expected Return/Bulan | L16: : | N16: ='Usulan Pembiayaan'!N18 | R16: ='Usulan Pembiayaan'!R18
A17: 10 | B17: Agsuran Perbulan | L17: : | N17: ='Usulan Pembiayaan'!N20
A19: HASIL SCORING DEBITUR
A20: A | B20: INFORMASI DASAR
B21: a. Jenis Kategori Nasabah | M21: ='Informasi Pokok'!D10
B22: b. Jenis Kelamin | M22: ='Informasi Pokok'!D12
B23: c. Usia | M23: ='Informasi Pokok'!I14
B24: d. Status Perkawinan | M24: ='Informasi Pokok'!D21
B25: e. Jumlah Tanggungan | M25: ='Informasi Pokok'!D22
B26: f. Tingkat Pendidikan | M26: ='Informasi Pokok'!D23
B27: g. Kepemilikan Tempat Tinggal | M27: ='Informasi Pokok'!D24
B28: h. Status Karyawan | M28: ='Informasi Pokok'!D25
B29: i. Bidang Usaha Pekerjaan | M29: ='Informasi Pokok'!D26
B30: j. Bonafiditas Perusahaan | M30: ='Informasi Pokok'!D27
B31: k. Usia Pensiun | M31: ='Informasi Pokok'!D28&" Tahun"
B32: l. Surat Keterangan Bekerja | M32: ='Informasi Pokok'!D29
B33: m. Slip Gaji | M33: ='Informasi Pokok'!D30
B34: n. Rekening Gaji | M34: ='Informasi Pokok'!D31
B35: o. Reputasi di Tempat Bekerja dan Tempat Tinggal | M35: ='Informasi Pokok'!D34
A36: B | B36: HUBUNGAN DENGAN BANK
B37: a. Hubungan Dengan Perbankan | M37: ='Informasi Pokok'!D48
B38: b. Riwayat Pembiayaan Bank (SLIK) | M38: ='Informasi Pokok'!D49
A39: C | B39: KAPASITAS MEMBAYAR PINJAMAN
B40: a. Jangka Waktu Pembiayaan | M40: =Parameter!T110
B41: b. Repayment Capacity (RPC) | M41: =TEXT('Usulan Pembiayaan'!B74,"#.##")&" ("&('Usulan Pembiayaan'!E74)&")"
B42: c. Permohonan Pembiayaan Ke- | M42: ='Informasi Pokok'!E53
A43: D | B43: AGUNAN | AB43: ='Aspek Non Keuangan'!#REF!
B44: a. Persentase Agunan | M44: =Parameter!T120
B45: b. Pengikatan Agunan | M45: ='Aspek Non Keuangan'!K77
A46: E | B46: ASURANSI | AB46: ='Aspek Non Keuangan'!#REF!
...

Sheet Rekomendasi AO
A1: REKOMENDASI USULAN PEMBIAYAAN
A2: Dari Kesimpulan tersebut maka calon Pemohon dapat direkomendasikan
A3: untuk mendpatkan pembiayaan sebagai berikut:
A4: - | B4: Nama | C4: : | D4: ='Informasi Pokok'!D11:J11
A5: - | B5: Maksimal Plaffond | C5: :
A6: - | B6: Harga Jual | C6: : | D6: =F11*D7+D5
A7: - | B7: Jangka Waktu | C7: : | E7: Bulan
A8: - | B8: Akad | C8: :
A9: - | B9: Tujuan Penggunaan | C9: :
A10: - | B10: Angsuran Pokok | C10: : | F10: =D5/D7
A11: - | B11: Angsuran Margin | C11: : | F11: =D5*D19
A12: - | B12: Angsuran Per bulan | C12: : | D12: =F10+F11
B13: Angsuran Per tgl 10 | C13: : | D13: =D12/2
B14: Angsuran Per tgl 25 | C14: : | D14: =D13
A15: - | B15: Biaya Asuransi | C15: :
A16: - | B16: Biaya Notaris | C16: :
A17: - | B17: Biaya ADM | C17: : | D17: =D5*2.5%
A18: - | B18: Tabungan Blokiran | C18: : | D18: =D12
A19: - | B19: Rate | C19: :
A20: - | B20: Skema Angsuran | C20: :
A24: Pengusul | D24: Menyetujui,
A29: Account Officer | D29: Koord. Marketing | G29: Kabag. Marketing

Sheet Jadang
A1: ="JADWAL ANGSURAN AKAD "&'Keputusan Pembiayaan'!N12&" ("&Q25&")" | H1: ="JADWAL ANGSURAN AKAD "&'Keputusan Pembiayaan'!N12&" ("&R25&")" | W1: 1,5% flat = 0,83% Efektif | Z1: =0.83*12 | AA1: =1.5*12
A2: ="Atas Nama "&'Keputusan Pembiayaan'!N11 | H2: ="Atas Nama "&'Keputusan Pembiayaan'!N11 | P2: =Q26 | W2: 1,5% efektif = 2,64% Flat | Z2: 1.15 | AA2: 1.83 | AB2: =AA2-Z2
B3: ='Informasi Pokok'!D6 | I3: 1
C4: Os. Pokok | D4: Pokok | E4: Margin | J4: OS. Pokok | K4: Pokok | L4: Margin | P4: Flat | Q4: jw | R4: =Q27 | Z4: =Z2*12 | AB4: =AA2*12 | AC4: =AB4-Z4 | AD4: =AC4/12
A5: No. | B5: Tanggal | F5: Total Angsuran | H5: No. | I5: Tanggal | M5: Total Angsuran | P5: Efektif | Q5: flat | R5: =P37 | T5: Flat | V5: Efektif
Q6: efektif | R6: =Q38 | T6: Pokok | U6: Margin | W6: Pokok | X6: margin | Y6: total
A8: 1 | B8: =IF(B3="","",DATE(YEAR(B3),MONTH(B3)+1,DAY(B3))) | C8: =P2 | D8: =IF('Usulan Pembiayaan'!$M$55="Flat",T8,W8)+67 | E8: =IF('Usulan Pembiayaan'!$M$55="Flat",U8,X8) | F8: =D8+E8 | H8: 1 | I8: =B8 | J8: =P2 | K8: =IF('Usulan Pembiayaan'!$M$55="Flat",W8,T8) | L8: =IF('Usulan Pembiayaan'!$M$55="Flat",X8,U8) | M8: =K8+L8+67 | P8: =PMT(R6%/12,R4,-P2,2) | Q8: 2200000 | T8: =(ROUNDDOWN(P2/R4,1)) | U8: =P2*R5 | V8: =P2 | W8: =Y8-X8 | X8: =(ROUNDDOWN(V8*$R$6/12,1)) | Y8: =PMT(R6/12,R4,-P2)
A9: 2 | B9: =IF(B8="","",DATE(YEAR(B8),MONTH(B8)+1,DAY(B8))) | C9: =C8-D8 | D9: =IF('Usulan Pembiayaan'!$M$55="Flat",T9,W9)+67 | E9: =IF('Usulan Pembiayaan'!$M$55="Flat",U9,X9) | F9: =D9+E9 | H9: 2 | I9: =IF(I8="","",DATE(YEAR(I8),MONTH(I8)+1,DAY(I8))) | J9: =J8-K8 | K9: =IF('Usulan Pembiayaan'!$M$55="Flat",W9,T9) | L9: =IF('Usulan Pembiayaan'!$M$55="Flat",X9,U9) | M9: =K9+L9+67 | P9: =(P2+U129)/R4 | Q9: 2034425.7 | T9: =IF(A9<=$R$4,$P$2/$R$4,0) | U9: =IF(A9<=$R$4,$U$8,0) | V9: =IF(A9<=$R$4,V8-W8,0) | W9: =Y9-X9 | X9: =IF(A9<=$R$4,V9*$R$6/12,0) | Y9: =IF(A9<=$R$4,$Y$8,0)
A10: 3 | B10: =IF(B9="","",DATE(YEAR(B9),MONTH(B9)+1,DAY(B9))) | C10: =C9-D9 | D10: =IF('Usulan Pembiayaan'!$M$55="Flat",T10,W10)+67 | E10: =IF('Usulan Pembiayaan'!$M$55="Flat",U10,X10) | F10: =D10+E10 | H10: 3 | I10: =IF(I9="","",DATE(YEAR(I9),MONTH(I9)+1,DAY(I9))) | J10: =J9-K9 | K10: =IF('Usulan Pembiayaan'!$M$55="Flat",W10,T10) | L10: =IF('Usulan Pembiayaan'!$M$55="Flat",X10,U10) | M10: =K10+L10+67 | P10: =P9-P8 | Q10: 1865815.8 | T10: =IF(A10<=$R$4,$P$2/$R$4,0) | U10: =IF(A10<=$R$4,$U$8,0) | V10: =IF(A10<=$R$4,V9-W9,0) | W10: =Y10-X10 | X10: =IF(A10<=$R$4,V10*$R$6/12,0) | Y10: =IF(A10<=$R$4,$Y$8,0)
A11: 4 | B11: =IF(B10="","",DATE(YEAR(B10),MONTH(B10)+1,DAY(B10))) | C11: =C10-D10 | D11: =IF('Usulan Pembiayaan'!$M$55="Flat",T11,W11)+67 | E11: =IF('Usulan Pembiayaan'!$M$55="Flat",U11,X11) | F11: =D11+E11 | H11: 4 | I11: =IF(I10="","",DATE(YEAR(I10),MONTH(I10)+1,DAY(I10))) | J11: =J10-K10 | K11: =IF('Usulan Pembiayaan'!$M$55="Flat",W11,T11) | L11: =IF('Usulan Pembiayaan'!$M$55="Flat",X11,U11) | M11: =K11+L11+67 | Q11: 1694114.8 | T11: =IF(A11<=$R$4,$P$2/$R$4,0) | U11: =IF(A11<=$R$4,$U$8,0) | V11: =IF(A11<=$R$4,V10-W10,0) | W11: =Y11-X11 | X11: =IF(A11<=$R$4,V11*$R$6/12,0) | Y11: =IF(A11<=$R$4,$Y$8,0)
A12: 5 | B12: =IF(B11="","",DATE(YEAR(B11),MONTH(B11)+1,DAY(B11))) | C12: =C11-D11 | D12: =IF('Usulan Pembiayaan'!$M$55="Flat",T12,W12)+67 | E12: =IF('Usulan Pembiayaan'!$M$55="Flat",U12,X12) | F12: =D12+E12 | H12: 5 | I12: =IF(I11="","",DATE(YEAR(I11),MONTH(I11)+1,DAY(I11))) | J12: =J11-K11 | K12: =IF('Usulan Pembiayaan'!$M$55="Flat",W12,T12) | L12: =IF('Usulan Pembiayaan'!$M$55="Flat",X12,U12) | M12: =K12+L12+67 | P12: =X129 | Q12: 1519266 | T12: =IF(A12<=$R$4,$P$2/$R$4,0) | U12: =IF(A12<=$R$4,$U$8,0) | V12: =IF(A12<=$R$4,V11-W11,0) | W12: =Y12-X12 | X12: =IF(A12<=$R$4,V12*$R$6/12,0) | Y12: =IF(A12<=$R$4,$Y$8,0)
A13: 6 | B13: =IF(B12="","",DATE(YEAR(B12),MONTH(B12)+1,DAY(B12))) | C13: =C12-D12 | D13: =IF('Usulan Pembiayaan'!$M$55="Flat",T13,W13)+67 | E13: =IF('Usulan Pembiayaan'!$M$55="Flat",U13,X13) | F13: =D13+E13 | H13: 6 | I13: =IF(I12="","",DATE(YEAR(I12),MONTH(I12)+1,DAY(I12))) | J13: =J12-K12 | K13: =IF('Usulan Pembiayaan'!$M$55="Flat",W13,T13) | L13: =IF('Usulan Pembiayaan'!$M$55="Flat",X13,U13) | M13: =K13+L13+67 | P13: =P12/P2*100/R4 | Q13: 1341211.5 | T13: =IF(A13<=$R$4,$P$2/$R$4,0) | U13: =IF(A13<=$R$4,$U$8,0) | V13: =IF(A13<=$R$4,V12-W12,0) | W13: =Y13-X13 | X13: =IF(A13<=$R$4,V13*$R$6/12,0) | Y13: =IF(A13<=$R$4,$Y$8,0)
A14: 7 | B14: =IF(B13="","",DATE(YEAR(B13),MONTH(B13)+1,DAY(B13))) | C14: =C13-D13 | D14: =IF('Usulan Pembiayaan'!$M$55="Flat",T14,W14)+67 | E14: =IF('Usulan Pembiayaan'!$M$55="Flat",U14,X14) | F14: =D14+E14 | H14: 7 | I14: =IF(I13="","",DATE(YEAR(I13),MONTH(I13)+1,DAY(I13))) | J14: =J13-K13 | K14: =IF('Usulan Pembiayaan'!$M$55="Flat",W14,T14) | L14: =IF('Usulan Pembiayaan'!$M$55="Flat",X14,U14) | M14: =K14+L14+67 | Q14: 1159892.8 | T14: =IF(A14<=$R$4,$P$2/$R$4,0) | U14: =IF(A14<=$R$4,$U$8,0) | V14: =IF(A14<=$R$4,V13-W13,0) | W14: =Y14-X14 | X14: =IF(A14<=$R$4,V14*$R$6/12,0) | Y14: =IF(A14<=$R$4,$Y$8,0)
A15: 8 | B15: =IF(B14="","",DATE(YEAR(B14),MONTH(B14)+1,DAY(B14))) | C15: =C14-D14 | D15: =IF('Usulan Pembiayaan'!$M$55="Flat",T15,W15)+67 | E15: =IF('Usulan Pembiayaan'!$M$55="Flat",U15,X15) | F15: =D15+E15 | H15: 8 | I15: =IF(I14="","",DATE(YEAR(I14),MONTH(I14)+1,DAY(I14))) | J15: =J14-K14 | K15: =IF('Usulan Pembiayaan'!$M$55="Flat",W15,T15) | L15: =IF('Usulan Pembiayaan'!$M$55="Flat",X15,U15) | M15: =K15+L15+67 | P15: =U129 | Q15: 975249.8 | T15: =IF(A15<=$R$4,$P$2/$R$4,0) | U15: =IF(A15<=$R$4,$U$8,0) | V15: =IF(A15<=$R$4,V14-W14,0) | W15: =Y15-X15 | X15: =IF(A15<=$R$4,V15*$R$6/12,0) | Y15: =IF(A15<=$R$4,$Y$8,0)
A16: 9 | B16: =IF(B15="","",DATE(YEAR(B15),MONTH(B15)+1,DAY(B15))) | C16: =C15-D15 | D16: =IF('Usulan Pembiayaan'!$M$55="Flat",T16,W16)+67 | E16: =IF('Usulan Pembiayaan'!$M$55="Flat",U16,X16) | F16: =D16+E16 | H16: 9 | I16: =IF(I15="","",DATE(YEAR(I15),MONTH(I15)+1,DAY(I15))) | J16: =J15-K15 | K16: =IF('Usulan Pembiayaan'!$M$55="Flat",W16,T16) | L16: =IF('Usulan Pembiayaan'!$M$55="Flat",X16,U16) | M16: =K16+L16+67 | P16: =P15/P2*100/R4 | Q16: 787221.8 | T16: =IF(A16<=$R$4,$P$2/$R$4,0) | U16: =IF(A16<=$R$4,$U$8,0) | V16: =IF(A16<=$R$4,V15-W15,0) | W16: =Y16-X16 | X16: =IF(A16<=$R$4,V16*$R$6/12,0) | Y16: =IF(A16<=$R$4,$Y$8,0)
A17: 10 | B17: =IF(B16="","",DATE(YEAR(B16),MONTH(B16)+1,DAY(B16))) | C17: =C16-D16 | D17: =IF('Usulan Pembiayaan'!$M$55="Flat",T17,W17)+67 | E17: =IF('Usulan Pembiayaan'!$M$55="Flat",U17,X17) | F17: =D17+E17 | H17: 10 | I17: =IF(I16="","",DATE(YEAR(I16),MONTH(I16)+1,DAY(I16))) | J17: =J16-K16 | K17: =IF('Usulan Pembiayaan'!$M$55="Flat",W17,T17) | L17: =IF('Usulan Pembiayaan'!$M$55="Flat",X17,U17) | M17: =K17+L17+67 | Q17: 595746.6 | T17: =IF(A17<=$R$4,$P$2/$R$4,0) | U17: =IF(A17<=$R$4,$U$8,0) | V17: =IF(A17<=$R$4,V16-W16,0) | W17: =Y17-X17 | X17: =IF(A17<=$R$4,V17*$R$6/12,0) | Y17: =IF(A17<=$R$4,$Y$8,0)
A18: 11 | B18: =IF(B17="","",DATE(YEAR(B17),MONTH(B17)+1,DAY(B17))) | C18: =C17-D17 | D18: =IF('Usulan Pembiayaan'!$M$55="Flat",T18,W18)+67 | E18: =IF('Usulan Pembiayaan'!$M$55="Flat",U18,X18) | F18: =D18+E18 | H18: 11 | I18: =IF(I17="","",DATE(YEAR(I17),MONTH(I17)+1,DAY(I17))) | J18: =J17-K17 | K18: =IF('Usulan Pembiayaan'!$M$55="Flat",W18,T18) | L18: =IF('Usulan Pembiayaan'!$M$55="Flat",X18,U18) | M18: =K18+L18+67 | Q18: 400760.9 | T18: =IF(A18<=$R$4,$P$2/$R$4,0) | U18: =IF(A18<=$R$4,$U$8,0) | V18: =IF(A18<=$R$4,V17-W17,0) | W18: =Y18-X18 | X18: =IF(A18<=$R$4,V18*$R$6/12,0) | Y18: =IF(A18<=$R$4,$Y$8,0)
A19: 12 | B19: =IF(B18="","",DATE(YEAR(B18),MONTH(B18)+1,DAY(B18))) | C19: =C18-D18 | D19: =IF('Usulan Pembiayaan'!$M$55="Flat",T19,W19)+67 | E19: =IF('Usulan Pembiayaan'!$M$55="Flat",U19,X19) | F19: =D19+E19 | H19: 12 | I19: =IF(I18="","",DATE(YEAR(I18),MONTH(I18)+1,DAY(I18))) | J19: =J18-K18 | K19: =IF('Usulan Pembiayaan'!$M$55="Flat",W19,T19) | L19: =IF('Usulan Pembiayaan'!$M$55="Flat",X19,U19) | M19: =K19+L19+67 | Q19: 202200.6 | T19: =IF(A19<=$R$4,$P$2/$R$4,0) | U19: =IF(A19<=$R$4,$U$8,0) | V19: =IF(A19<=$R$4,V18-W18,0) | W19: =Y19-X19 | X19: =IF(A19<=$R$4,V19*$R$6/12,0) | Y19: =IF(A19<=$R$4,$Y$8,0)
A20: 13 | B20: =IF(B19="","",DATE(YEAR(B19),MONTH(B19)+1,DAY(B19))) | C20: =C19-D19 | D20: =IF('Usulan Pembiayaan'!$M$55="Flat",T20,W20)+67 | E20: =IF('Usulan Pembiayaan'!$M$55="Flat",U20,X20) | F20: =D20+E20 | H20: 13 | I20: =IF(I19="","",DATE(YEAR(I19),MONTH(I19)+1,DAY(I19))) | J20: =J19-K19 | K20: =IF('Usulan Pembiayaan'!$M$55="Flat",W20,T20) | L20: =IF('Usulan Pembiayaan'!$M$55="Flat",X20,U20) | M20: =K20+L20+67 | T20: =IF(A20<=$R$4,$P$2/$R$4,0) | U20: =IF(A20<=$R$4,$U$8,0) | V20: =IF(A20<=$R$4,V19-W19,0) | W20: =Y20-X20 | X20: =IF(A20<=$R$4,V20*$R$6/12,0) | Y20: =IF(A20<=$R$4,$Y$8,0)
A21: 14 | B21: =IF(B20="","",DATE(YEAR(B20),MONTH(B20)+1,DAY(B20))) | C21: =C20-D20 | D21: =IF('Usulan Pembiayaan'!$M$55="Flat",T21,W21)+67 | E21: =IF('Usulan Pembiayaan'!$M$55="Flat",U21,X21) | F21: =D21+E21 | H21: 14 | I21: =IF(I20="","",DATE(YEAR(I20),MONTH(I20)+1,DAY(I20))) | J21: =J20-K20 | K21: =IF('Usulan Pembiayaan'!$M$55="Flat",W21,T21) | L21: =IF('Usulan Pembiayaan'!$M$55="Flat",X21,U21) | M21: =K21+L21+67 | T21: =IF(A21<=$R$4,$P$2/$R$4,0) | U21: =IF(A21<=$R$4,$U$8,0) | V21: =IF(A21<=$R$4,V20-W20,0) | W21: =Y21-X21 | X21: =IF(A21<=$R$4,V21*$R$6/12,0) | Y21: =IF(A21<=$R$4,$Y$8,0)
A22: 15 | B22: =IF(B21="","",DATE(YEAR(B21),MONTH(B21)+1,DAY(B21))) | C22: =C21-D21 | D22: =IF('Usulan Pembiayaan'!$M$55="Flat",T22,W22)+67 | E22: =IF('Usulan Pembiayaan'!$M$55="Flat",U22,X22) | F22: =D22+E22 | H22: 15 | I22: =IF(I21="","",DATE(YEAR(I21),MONTH(I21)+1,DAY(I21))) | J22: =J21-K21 | K22: =IF('Usulan Pembiayaan'!$M$55="Flat",W22,T22) | L22: =IF('Usulan Pembiayaan'!$M$55="Flat",X22,U22) | M22: =K22+L22+67 | T22: =IF(A22<=$R$4,$P$2/$R$4,0) | U22: =IF(A22<=$R$4,$U$8,0) | V22: =IF(A22<=$R$4,V21-W21,0) | W22: =Y22-X22 | X22: =IF(A22<=$R$4,V22*$R$6/12,0) | Y22: =IF(A22<=$R$4,$Y$8,0)
A23: 16 | B23: =IF(B22="","",DATE(YEAR(B22),MONTH(B22)+1,DAY(B22))) | C23: =C22-D22 | D23: =IF('Usulan Pembiayaan'!$M$55="Flat",T23,W23)+67 | E23: =IF('Usulan Pembiayaan'!$M$55="Flat",U23,X23) | F23: =D23+E23 | H23: 16 | I23: =IF(I22="","",DATE(YEAR(I22),MONTH(I22)+1,DAY(I22))) | J23: =J22-K22 | K23: =IF('Usulan Pembiayaan'!$M$55="Flat",W23,T23) | L23: =IF('Usulan Pembiayaan'!$M$55="Flat",X23,U23) | M23: =K23+L23+67 | T23: =IF(A23<=$R$4,$P$2/$R$4,0) | U23: =IF(A23<=$R$4,$U$8,0) | V23: =IF(A23<=$R$4,V22-W22,0) | W23: =Y23-X23 | X23: =IF(A23<=$R$4,V23*$R$6/12,0) | Y23: =IF(A23<=$R$4,$Y$8,0)
A24: 17 | B24: =IF(B23="","",DATE(YEAR(B23),MONTH(B23)+1,DAY(B23))) | C24: =C23-D23 | D24: =IF('Usulan Pembiayaan'!$M$55="Flat",T24,W24)+67 | E24: =IF('Usulan Pembiayaan'!$M$55="Flat",U24,X24) | F24: =D24+E24 | H24: 17 | I24: =IF(I23="","",DATE(YEAR(I23),MONTH(I23)+1,DAY(I23))) | J24: =J23-K23 | K24: =IF('Usulan Pembiayaan'!$M$55="Flat",W24,T24) | L24: =IF('Usulan Pembiayaan'!$M$55="Flat",X24,U24) | M24: =K24+L24+67 | P24: DATA | T24: =IF(A24<=$R$4,$P$2/$R$4,0) | U24: =IF(A24<=$R$4,$U$8,0) | V24: =IF(A24<=$R$4,V23-W23,0) | W24: =Y24-X24 | X24: =IF(A24<=$R$4,V24*$R$6/12,0) | Y24: =IF(A24<=$R$4,$Y$8,0)
A25: 18 | B25: =IF(B24="","",DATE(YEAR(B24),MONTH(B24)+1,DAY(B24))) | C25: =C24-D24 | D25: =IF('Usulan Pembiayaan'!$M$55="Flat",T25,W25)+67 | E25: =IF('Usulan Pembiayaan'!$M$55="Flat",U25,X25) | F25: =D25+E25 | H25: 18 | I25: =IF(I24="","",DATE(YEAR(I24),MONTH(I24)+1,DAY(I24))) | J25: =J24-K24 | K25: =IF('Usulan Pembiayaan'!$M$55="Flat",W25,T25) | L25: =IF('Usulan Pembiayaan'!$M$55="Flat",X25,U25) | M25: =K25+L25+67 | P25: Jenis Margin | Q25: ='Usulan Pembiayaan'!M55 | R25: =IF(Q25="Flat","Efektif","Flat") | T25: =IF(A25<=$R$4,$P$2/$R$4,0) | U25: =IF(A25<=$R$4,$U$8,0) | V25: =IF(A25<=$R$4,V24-W24,0) | W25: =Y25-X25 | X25: =IF(A25<=$R$4,V25*$R$6/12,0) | Y25: =IF(A25<=$R$4,$Y$8,0)
A26: 19 | B26: =IF(B25="","",DATE(YEAR(B25),MONTH(B25)+1,DAY(B25))) | C26: =C25-D25 | D26: =IF('Usulan Pembiayaan'!$M$55="Flat",T26,W26)+67 | E26: =IF('Usulan Pembiayaan'!$M$55="Flat",U26,X26) | F26: =D26+E26 | H26: 19 | I26: =IF(I25="","",DATE(YEAR(I25),MONTH(I25)+1,DAY(I25))) | J26: =J25-K25 | K26: =IF('Usulan Pembiayaan'!$M$55="Flat",W26,T26) | L26: =IF('Usulan Pembiayaan'!$M$55="Flat",X26,U26) | M26: =K26+L26+67 | P26: Plafond | Q26: ='Usulan Pembiayaan'!J53 | T26: =IF(A26<=$R$4,$P$2/$R$4,0) | U26: =IF(A26<=$R$4,$U$8,0) | V26: =IF(A26<=$R$4,V25-W25,0) | W26: =Y26-X26 | X26: =IF(A26<=$R$4,V26*$R$6/12,0) | Y26: =IF(A26<=$R$4,$Y$8,0)
A27: 20 | B27: =IF(B26="","",DATE(YEAR(B26),MONTH(B26)+1,DAY(B26))) | C27: =C26-D26 | D27: =IF('Usulan Pembiayaan'!$M$55="Flat",T27,W27)+67 | E27: =IF('Usulan Pembiayaan'!$M$55="Flat",U27,X27) | F27: =D27+E27 | H27: 20 | I27: =IF(I26="","",DATE(YEAR(I26),MONTH(I26)+1,DAY(I26))) | J27: =J26-K26 | K27: =IF('Usulan Pembiayaan'!$M$55="Flat",W27,T27) | L27: =IF('Usulan Pembiayaan'!$M$55="Flat",X27,U27) | M27: =K27+L27+67 | P27: Jangka Waktu | Q27: ='Usulan Pembiayaan'!J54 | T27: =IF(A27<=$R$4,$P$2/$R$4,0) | U27: =IF(A27<=$R$4,$U$8,0) | V27: =IF(A27<=$R$4,V26-W26,0) | W27: =Y27-X27 | X27: =IF(A27<=$R$4,V27*$R$6/12,0) | Y27: =IF(A27<=$R$4,$Y$8,0)
A28: 21 | B28: =IF(B27="","",DATE(YEAR(B27),MONTH(B27)+1,DAY(B27))) | C28: =C27-D27 | D28: =IF('Usulan Pembiayaan'!$M$55="Flat",T28,W28)+67 | E28: =IF('Usulan Pembiayaan'!$M$55="Flat",U28,X28) | F28: =D28+E28 | H28: 21 | I28: =IF(I27="","",DATE(YEAR(I27),MONTH(I27)+1,DAY(I27))) | J28: =J27-K27 | K28: =IF('Usulan Pembiayaan'!$M$55="Flat",W28,T28) | L28: =IF('Usulan Pembiayaan'!$M$55="Flat",X28,U28) | M28: =K28+L28+67 | P28: %Margin/bulan | Q28: ='Usulan Pembiayaan'!J55 | T28: =IF(A28<=$R$4,$P$2/$R$4,0) | U28: =IF(A28<=$R$4,$U$8,0) | V28: =IF(A28<=$R$4,V27-W27,0) | W28: =Y28-X28 | X28: =IF(A28<=$R$4,V28*$R$6/12,0) | Y28: =IF(A28<=$R$4,$Y$8,0)
A29: 22 | B29: =IF(B28="","",DATE(YEAR(B28),MONTH(B28)+1,DAY(B28))) | C29: =C28-D28 | D29: =IF('Usulan Pembiayaan'!$M$55="Flat",T29,W29)+67 | E29: =IF('Usulan Pembiayaan'!$M$55="Flat",U29,X29) | F29: =D29+E29 | H29: 22 | I29: =IF(I28="","",DATE(YEAR(I28),MONTH(I28)+1,DAY(I28))) | J29: =J28-K28 | K29: =IF('Usulan Pembiayaan'!$M$55="Flat",W29,T29) | L29: =IF('Usulan Pembiayaan'!$M$55="Flat",X29,U29) | M29: =K29+L29+67 | P29: Angsuran | Q29: =IF(Q25="Flat",((Q26/Q27)+(Q26*Q28)),PMT(Q28,Q27,-Q26)) | T29: =IF(A29<=$R$4,$P$2/$R$4,0) | U29: =IF(A29<=$R$4,$U$8,0) | V29: =IF(A29<=$R$4,V28-W28,0) | W29: =Y29-X29 | X29: =IF(A29<=$R$4,V29*$R$6/12,0) | Y29: =IF(A29<=$R$4,$Y$8,0)
A30: 23 | B30: =IF(B29="","",DATE(YEAR(B29),MONTH(B29)+1,DAY(B29))) | C30: =C29-D29 | D30: =IF('Usulan Pembiayaan'!$M$55="Flat",T30,W30)+67 | E30: =IF('Usulan Pembiayaan'!$M$55="Flat",U30,X30) | F30: =D30+E30 | H30: 23 | I30: =IF(I29="","",DATE(YEAR(I29),MONTH(I29)+1,DAY(I29))) | J30: =J29-K29 | K30: =IF('Usulan Pembiayaan'!$M$55="Flat",W30,T30) | L30: =IF('Usulan Pembiayaan'!$M$55="Flat",X30,U30) | M30: =K30+L30+67 | T30: =IF(A30<=$R$4,$P$2/$R$4,0) | U30: =IF(A30<=$R$4,$U$8,0) | V30: =IF(A30<=$R$4,V29-W29,0) | W30: =Y30-X30 | X30: =IF(A30<=$R$4,V30*$R$6/12,0) | Y30: =IF(A30<=$R$4,$Y$8,0)
A31: 24 | B31: =IF(B30="","",DATE(YEAR(B30),MONTH(B30)+1,DAY(B30))) | C31: =C30-D30 | D31: =IF('Usulan Pembiayaan'!$M$55="Flat",T31,W31)+67 | E31: =IF('Usulan Pembiayaan'!$M$55="Flat",U31,X31) | F31: =D31+E31 | H31: 24 | I31: =IF(I30="","",DATE(YEAR(I30),MONTH(I30)+1,DAY(I30))) | J31: =J30-K30 | K31: =IF('Usulan Pembiayaan'!$M$55="Flat",W31,T31) | L31: =IF('Usulan Pembiayaan'!$M$55="Flat",X31,U31) | M31: =K31+L31+67 | P31: KONVERSI | T31: =IF(A31<=$R$4,$P$2/$R$4,0) | U31: =IF(A31<=$R$4,$U$8,0) | V31: =IF(A31<=$R$4,V30-W30,0) | W31: =Y31-X31 | X31: =IF(A31<=$R$4,V31*$R$6/12,0) | Y31: =IF(A31<=$R$4,$Y$8,0)
A32: 25 | B32: =IF(B31="","",DATE(YEAR(B31),MONTH(B31)+1,DAY(B31))) | C32: =C31-D31 | D32: =IF('Usulan Pembiayaan'!$M$55="Flat",T32,W32)+67 | E32: =IF('Usulan Pembiayaan'!$M$55="Flat",U32,X32) | F32: =D32+E32 | H32: 25 | I32: =IF(I31="","",DATE(YEAR(I31),MONTH(I31)+1,DAY(I31))) | J32: =J31-K31 | K32: =IF('Usulan Pembiayaan'!$M$55="Flat",W32,T32) | L32: =IF('Usulan Pembiayaan'!$M$55="Flat",X32,U32) | M32: =K32+L32+67 | P32: Jenis Margin | Q32: =IF(Q25="Flat","Efektif","Flat") | T32: =IF(A32<=$R$4,$P$2/$R$4,0) | U32: =IF(A32<=$R$4,$U$8,0) | V32: =IF(A32<=$R$4,V31-W31,0) | W32: =Y32-X32 | X32: =IF(A32<=$R$4,V32*$R$6/12,0) | Y32: =IF(A32<=$R$4,$Y$8,0)
A33: 26 | B33: =IF(B32="","",DATE(YEAR(B32),MONTH(B32)+1,DAY(B32))) | C33: =C32-D32 | D33: =IF('Usulan Pembiayaan'!$M$55="Flat",T33,W33)+67 | E33: =IF('Usulan Pembiayaan'!$M$55="Flat",U33,X33) | F33: =D33+E33 | H33: 26 | I33: =IF(I32="","",DATE(YEAR(I32),MONTH(I32)+1,DAY(I32))) | J33: =J32-K32 | K33: =IF('Usulan Pembiayaan'!$M$55="Flat",W33,T33) | L33: =IF('Usulan Pembiayaan'!$M$55="Flat",X33,U33) | M33: =K33+L33+67 | P33: %Margin/bulan | Q33: =IF(Q32="Flat",((Q29/Q26)-(1/Q27)),RATE(Q27,Q29,-Q26)) | T33: =IF(A33<=$R$4,$P$2/$R$4,0) | U33: =IF(A33<=$R$4,$U$8,0) | V33: =IF(A33<=$R$4,V32-W32,0) | W33: =Y33-X33 | X33: =IF(A33<=$R$4,V33*$R$6/12,0) | Y33: =IF(A33<=$R$4,$Y$8,0)
A34: 27 | B34: =IF(B33="","",DATE(YEAR(B33),MONTH(B33)+1,DAY(B33))) | C34: =C33-D33 | D34: =IF('Usulan Pembiayaan'!$M$55="Flat",T34,W34)+67 | E34: =IF('Usulan Pembiayaan'!$M$55="Flat",U34,X34) | F34: =D34+E34 | H34: 27 | I34: =IF(I33="","",DATE(YEAR(I33),MONTH(I33)+1,DAY(I33))) | J34: =J33-K33 | K34: =IF('Usulan Pembiayaan'!$M$55="Flat",W34,T34) | L34: =IF('Usulan Pembiayaan'!$M$55="Flat",X34,U34) | M34: =K34+L34+67 | P34: Angsuran | Q34: =IF(Q32="Flat",((Q26/Q27)+(Q26*Q33)),IF(Q32="Efektif",PMT(Q33,Q27,-Q26))) | T34: =IF(A34<=$R$4,$P$2/$R$4,0) | U34: =IF(A34<=$R$4,$U$8,0) | V34: =IF(A34<=$R$4,V33-W33,0) | W34: =Y34-X34 | X34: =IF(A34<=$R$4,V34*$R$6/12,0) | Y34: =IF(A34<=$R$4,$Y$8,0)
A35: 28 | B35: =IF(B34="","",DATE(YEAR(B34),MONTH(B34)+1,DAY(B34))) | C35: =C34-D34 | D35: =IF('Usulan Pembiayaan'!$M$55="Flat",T35,W35)+67 | E35: =IF('Usulan Pembiayaan'!$M$55="Flat",U35,X35) | F35: =D35+E35 | H35: 28 | I35: =IF(I34="","",DATE(YEAR(I34),MONTH(I34)+1,DAY(I34))) | J35: =J34-K34 | K35: =IF('Usulan Pembiayaan'!$M$55="Flat",W35,T35) | L35: =IF('Usulan Pembiayaan'!$M$55="Flat",X35,U35) | M35: =K35+L35+67 | T35: =IF(A35<=$R$4,$P$2/$R$4,0) | U35: =IF(A35<=$R$4,$U$8,0) | V35: =IF(A35<=$R$4,V34-W34,0) | W35: =Y35-X35 | X35: =IF(A35<=$R$4,V35*$R$6/12,0) | Y35: =IF(A35<=$R$4,$Y$8,0)
A36: 29 | B36: =IF(B35="","",DATE(YEAR(B35),MONTH(B35)+1,DAY(B35))) | C36: =C35-D35 | D36: =IF('Usulan Pembiayaan'!$M$55="Flat",T36,W36)+67 | E36: =IF('Usulan Pembiayaan'!$M$55="Flat",U36,X36) | F36: =D36+E36 | H36: 29 | I36: =IF(I35="","",DATE(YEAR(I35),MONTH(I35)+1,DAY(I35))) | J36: =J35-K35 | K36: =IF('Usulan Pembiayaan'!$M$55="Flat",W36,T36) | L36: =IF('Usulan Pembiayaan'!$M$55="Flat",X36,U36) | M36: =K36+L36+67 | P36: FLAT | Q36: EFEKTIF | T36: =IF(A36<=$R$4,$P$2/$R$4,0) | U36: =IF(A36<=$R$4,$U$8,0) | V36: =IF(A36<=$R$4,V35-W35,0) | W36: =Y36-X36 | X36: =IF(A36<=$R$4,V36*$R$6/12,0) | Y36: =IF(A36<=$R$4,$Y$8,0)
A37: 30 | B37: =IF(B36="","",DATE(YEAR(B36),MONTH(B36)+1,DAY(B36))) | C37: =C36-D36 | D37: =IF('Usulan Pembiayaan'!$M$55="Flat",T37,W37)+67 | E37: =IF('Usulan Pembiayaan'!$M$55="Flat",U37,X37) | F37: =D37+E37 | H37: 30 | I37: =IF(I36="","",DATE(YEAR(I36),MONTH(I36)+1,DAY(I36))) | J37: =J36-K36 | K37: =IF('Usulan Pembiayaan'!$M$55="Flat",W37,T37) | L37: =IF('Usulan Pembiayaan'!$M$55="Flat",X37,U37) | M37: =K37+L37+67 | P37: =IF(Q32="Flat",Q33,IF(Q32="Efektif",Q28)) | Q37: =IF(Q32="Efektif",Q33,IF(Q32="Flat",Q28)) | T37: =IF(A37<=$R$4,$P$2/$R$4,0) | U37: =IF(A37<=$R$4,$U$8,0) | V37: =IF(A37<=$R$4,V36-W36,0) | W37: =Y37-X37 | X37: =IF(A37<=$R$4,V37*$R$6/12,0) | Y37: =IF(A37<=$R$4,$Y$8,0)
A38: 31 | B38: =IF(B37="","",DATE(YEAR(B37),MONTH(B37)+1,DAY(B37))) | C38: =C37-D37 | D38: =IF('Usulan Pembiayaan'!$M$55="Flat",T38,W38)+67 | E38: =IF('Usulan Pembiayaan'!$M$55="Flat",U38,X38) | F38: =D38+E38 | H38: 31 | I38: =IF(I37="","",DATE(YEAR(I37),MONTH(I37)+1,DAY(I37))) | J38: =J37-K37 | K38: =IF('Usulan Pembiayaan'!$M$55="Flat",W38,T38) | L38: =IF('Usulan Pembiayaan'!$M$55="Flat",X38,U38) | M38: =K38+L38+67 | P38: =P37*12 | Q38: =Q37*12 | T38: =IF(A38<=$R$4,$P$2/$R$4,0) | U38: =IF(A38<=$R$4,$U$8,0) | V38: =IF(A38<=$R$4,V37-W37,0) | W38: =Y38-X38 | X38: =IF(A38<=$R$4,V38*$R$6/12,0) | Y38: =IF(A38<=$R$4,$Y$8,0)
A39: 32 | B39: =IF(B38="","",DATE(YEAR(B38),MONTH(B38)+1,DAY(B38))) | C39: =C38-D38 | D39: =IF('Usulan Pembiayaan'!$M$55="Flat",T39,W39)+67 | E39: =IF('Usulan Pembiayaan'!$M$55="Flat",U39,X39) | F39: =D39+E39 | H39: 32 | I39: =IF(I38="","",DATE(YEAR(I38),MONTH(I38)+1,DAY(I38))) | J39: =J38-K38 | K39: =IF('Usulan Pembiayaan'!$M$55="Flat",W39,T39) | L39: =IF('Usulan Pembiayaan'!$M$55="Flat",X39,U39) | M39: =K39+L39+67 | T39: =IF(A39<=$R$4,$P$2/$R$4,0) | U39: =IF(A39<=$R$4,$U$8,0) | V39: =IF(A39<=$R$4,V38-W38,0) | W39: =Y39-X39 | X39: =IF(A39<=$R$4,V39*$R$6/12,0) | Y39: =IF(A39<=$R$4,$Y$8,0)
A40: 33 | B40: =IF(B39="","",DATE(YEAR(B39),MONTH(B39)+1,DAY(B39))) | C40: =C39-D39 | D40: =IF('Usulan Pembiayaan'!$M$55="Flat",T40,W40)+67 | E40: =IF('Usulan Pembiayaan'!$M$55="Flat",U40,X40) | F40: =D40+E40 | H40: 33 | I40: =IF(I39="","",DATE(YEAR(I39),MONTH(I39)+1,DAY(I39))) | J40: =J39-K39 | K40: =IF('Usulan Pembiayaan'!$M$55="Flat",W40,T40) | L40: =IF('Usulan Pembiayaan'!$M$55="Flat",X40,U40) | M40: =K40+L40+67 | T40: =IF(A40<=$R$4,$P$2/$R$4,0) | U40: =IF(A40<=$R$4,$U$8,0) | V40: =IF(A40<=$R$4,V39-W39,0) | W40: =Y40-X40 | X40: =IF(A40<=$R$4,V40*$R$6/12,0) | Y40: =IF(A40<=$R$4,$Y$8,0)
A41: 34 | B41: =IF(B40="","",DATE(YEAR(B40),MONTH(B40)+1,DAY(B40))) | C41: =C40-D40 | D41: =IF('Usulan Pembiayaan'!$M$55="Flat",T41,W41)+67 | E41: =IF('Usulan Pembiayaan'!$M$55="Flat",U41,X41) | F41: =D41+E41 | H41: 34 | I41: =IF(I40="","",DATE(YEAR(I40),MONTH(I40)+1,DAY(I40))) | J41: =J40-K40 | K41: =IF('Usulan Pembiayaan'!$M$55="Flat",W41,T41) | L41: =IF('Usulan Pembiayaan'!$M$55="Flat",X41,U41) | M41: =K41+L41+67 | T41: =IF(A41<=$R$4,$P$2/$R$4,0) | U41: =IF(A41<=$R$4,$U$8,0) | V41: =IF(A41<=$R$4,V40-W40,0) | W41: =Y41-X41 | X41: =IF(A41<=$R$4,V41*$R$6/12,0) | Y41: =IF(A41<=$R$4,$Y$8,0)
...

Sheet Parameter
A1: PARAMETER KREDIT SCORING KCR | H1: EXISTING | L1: <=50juta
H2: BBT (a) | I2: % Fktr (b) | J2: % Var © | K2: Nilai = a x b x c | L2: BBT (a) | M2: % Fktr (b) | N2: % Var © | O2: Nilai = a x b x c
A4: STEP 1 - INFORMASI DASAR
A5: (a) | B5: Usia Calon Nasabah | U5: Tering
D6: 1 | E6: =IF($G$32<=2,J254,K254) | H6: 100 | I6: 0.15 | J6: 0.25 | K6: =H6*I6*J6 | L6: 50 | M6: 0.05 | N6: 0.3 | O6: =L6*M6*N6
D7: 2 | E7: =IF($G$32<=2,J255,K255) | H7: 80 | I7: 0.15 | J7: 0.25 | K7: =H7*I7*J7 | L7: 85 | M7: 0.05 | N7: 0.3 | O7: =L7*M7*N7 | U7: =VLOOKUP('Informasi Pokok'!I14,Parameter!E6:K9,7,0)
D8: 3 | E8: =IF($G$32<=2,J256,K256) | H8: 60 | I8: 0.15 | J8: 0.25 | K8: =H8*I8*J8 | L8: 100 | M8: 0.05 | N8: 0.3 | O8: =L8*M8*N8
D9: 4 | E9: =IF($G$32<=2,J257,K257) | H9: 40 | I9: 0.15 | J9: 0.25 | K9: =H9*I9*J9 | L9: 70 | M9: 0.05 | N9: 0.3 | O9: =L9*M9*N9 | P9: =K6 | Q9: =K7 | R9: =K8 | S9: =K9
A10: (b) | B10: Status Perkawinan
D11: 1 | E11: Menikah | H11: 100 | I11: 0.15 | J11: 0.2 | K11: =H11*I11*J11 | L11: 80 | M11: 0.05 | N11: 0.25 | O11: =L11*M11*N11
D12: 2 | E12: Lajang | H12: 80 | I12: 0.15 | J12: 0.2 | K12: =H12*I12*J12 | L12: 100 | M12: 0.05 | N12: 0.25 | O12: =L12*M12*N12 | P12: =K11 | Q12: =K12 | S12: =K13 | T12: lajang | U12: =VLOOKUP('Informasi Pokok'!D21,Parameter!E11:K13,7,0)
D13: 3 | E13: Cerai | H13: 65 | I13: 0.15 | J13: 0.2 | K13: =H13*I13*J13
A14: (c) | B14: Jumlah Tanggungan
D15: 1 | E15: > 5 Orang | H15: 25 | I15: 0.1 | J15: 0.3 | K15: =H15*I15*J15 | L15: 25 | M15: 0.05 | N15: 0.45 | O15: =L15*M15*N15
D16: 2 | E16: 3 - 5 Orang | H16: 50 | I16: 0.1 | J16: 0.3 | K16: =H16*I16*J16 | L16: 50 | M16: 0.05 | N16: 0.45 | O16: =L16*M16*N16
D17: 3 | E17: 1 - 2 Orang | H17: 75 | I17: 0.1 | J17: 0.3 | K17: =H17*I17*J17 | L17: 75 | M17: 0.05 | N17: 0.45 | O17: =L17*M17*N17
D18: 4 | E18: Tidak Mempunyai Tanggungan | H18: 100 | I18: 0.1 | J18: 0.3 | K18: =H18*I18*J18 | L18: 100 | M18: 0.05 | N18: 0.45 | O18: =L18*M18*N18 | P18: =K18 | Q18: =K17 | R18: =K16 | S18: =K15 | U18: =VLOOKUP('Informasi Pokok'!$D$22,Parameter!$E$15:$K$18,7,0)
A19: (d) | B19: Tingkat Pendidikan
D20: 1 | E20: SMA | H20: 25 | I20: 0.15 | J20: 0.2 | K20: =H20*I20*J20
D21: 2 | E21: D1 - D4 | H21: 50 | I21: 0.15 | J21: 0.2 | K21: =H21*I21*J21
D22: 3 | E22: S1 | H22: 75 | I22: 0.15 | J22: 0.2 | K22: =H22*I22*J22
D23: 4 | E23: S2 - S3 | H23: 100 | I23: 0.15 | J23: 0.2 | K23: =H23*I23*J23 | P23: =K23 | Q23: =K22 | R23: =K21 | S23: =K20 | U23: =VLOOKUP('Informasi Pokok'!$D$23,Parameter!E20:K23,7,0)
A26: (a) | B26: Kepemilikan tempat tinggal
D27: 1 | E27: Sewa | H27: 25 | I27: 0.25 | J27: 0.2 | K27: =H27*I27*J27 | L27: 25 | M27: 0.1 | N27: 0.6 | O27: =L27*M27*N27
D28: 2 | E28: Lain-lain (Menumpang) | H28: 50 | I28: 0.25 | J28: 0.2 | K28: =H28*I28*J28 | L28: 50 | M28: 0.1 | N28: 0.6 | O28: =L28*M28*N28
D29: 3 | E29: Angsuran | H29: 75 | I29: 0.25 | J29: 0.2 | K29: =H29*I29*J29 | L29: 75 | M29: 0.1 | N29: 0.6 | O29: =L29*M29*N29
D30: 4 | E30: Milik sendiri | H30: 100 | I30: 0.25 | J30: 0.2 | K30: =H30*I30*J30 | L30: 100 | M30: 0.1 | N30: 0.6 | O30: =L30*M30*N30 | P30: =K30 | Q30: =K29 | R30: =K28 | S30: =K27 | U30: =VLOOKUP('Informasi Pokok'!$D$24,Parameter!E27:K30,7,0)
A31: (b) | B31: Status Karyawan
D32: 1 | E32: TNI/POLRI | F32: 1 | G32: =VLOOKUP('Informasi Pokok'!D25,Parameter!E32:F36,2,0) | H32: 20 | I32: 0.2 | J32: 0.25 | K32: =H32*I32*J32 | L32: 25 | M32: 0.1 | N32: 0.4 | O32: =L32*M32*N32
D33: 2 | E33: PNS | F33: 2 | H33: 100 | I33: 0.2 | J33: 0.25 | K33: =H33*I33*J33 | L33: 50 | M33: 0.1 | N33: 0.4 | O33: =L33*M33*N33
D34: 3 | E34: Kontrak Swasta | F34: 3 | H34: 40 | I34: 0.2 | J34: 0.25 | K34: =H34*I34*J34 | L34: 75 | M34: 0.1 | N34: 0.4 | O34: =L34*M34*N34
D35: 4 | E35: Kontrak ASN/PPPK | F35: 4 | H35: 60 | I35: 0.2 | J35: 0.25 | K35: =H35*I35*J35 | L35: 100 | M35: 0.1 | N35: 0.4 | O35: =L35*M35*N35
D36: 5 | E36: Tetap Swasta | F36: 5 | H36: 80 | I36: 0.2 | J36: 0.25 | K36: =H36*I36*J36 | P36: =K33 | Q36: =K35 | R36: =K34 | S36: =K33 | U36: =VLOOKUP('Informasi Pokok'!$D$25,Parameter!E32:K36,7,0)
A37: (b) | B37: Bidang Usaha Pekerjaan
D38: 1 | E38: Perdagangan | H38: 20 | I38: 0.2 | J38: 0.3 | K38: =H38*I38*J38 | L38: 25 | M38: 0.1 | N38: 0.4 | O38: =L38*M38*N38
D39: 2 | E39: Jasa | H39: 40 | I39: 0.2 | J39: 0.3 | K39: =H39*I39*J39 | L39: 50 | M39: 0.1 | N39: 0.4 | O39: =L39*M39*N39
D40: 3 | E40: Pendidikan | H40: 60 | I40: 0.2 | J40: 0.3 | K40: =H40*I40*J40 | L40: 75 | M40: 0.1 | N40: 0.4 | O40: =L40*M40*N40
D41: 4 | E41: Kesehatan | H41: 80 | I41: 0.2 | J41: 0.3 | K41: =H41*I41*J41 | L41: 100 | M41: 0.1 | N41: 0.4 | O41: =L41*M41*N41
D42: 5 | E42: Pemerintahan | H42: 100 | I42: 0.2 | J42: 0.3 | K42: =H42*I42*J42
A43: (b) | B43: Bonafiditas Perusahaan
...

Sheet Rating
B3: HIGH | C3: LOW | D3: RANK | E3: TINGKAT RATING | G3: RANK | H3: PD | I3: PENJELASAN DARI RATING
A4: 1 | B4: 100 | C4: 98 | D4: 1 | E4: AAA | F4: Outstanding | G4: 1 | H4: 0.0003 | I4: Ini adalah rating tertinggi dan terbaik yang diberikan kepada debitur. Kapasitas debitur untuk memenuhi komitmen keuangannya pada pinjaman bank dipandang tidak diragukan.
A5: 2 | B5: 97 | C5: 95 | D5: 2 | E5: AA+ | F5: Strong | G5: 2 | H5: 0.0003 | I5: Debitur yang diberikan rating ‘AA+’ hanya berbeda sedikit dari debitur yang diberikan rating tertinggi (AAA). Kapasitas debitur untuk memenuhi komitmen keuangannya pada pinjamannya sangat baik.
A6: 3 | B6: 94 | C6: 92 | D6: 3 | E6: AA | F6: Strong | G6: 3 | H6: 0.0003 | I6: Debitur yang diberikan rating ‘AA’ hanya berbeda sedikit dari debitur yang diberikan rating tertinggi (AAA). Kapasitas debitur untuk memenuhi komitmen keuangannya pada pinjamannya sangat baik.
A7: 4 | B7: 91 | C7: 89 | D7: 4 | E7: AA- | F7: Strong | G7: 4 | H7: 0.0003 | I7: Debitur yang diberikan rating ‘AA-’ hanya berbeda sedikit dari debitur yang diberikan rating tertinggi (AAA). Kapasitas debitur untuk memenuhi komitmen keuangannya pada pinjamannya sangat baik.
A8: 5 | B8: 88 | C8: 86 | D8: 5 | E8: A+ | F8: Good | G8: 5 | H8: 0.0006 | I8: Debitur yang diberikan rating ‘A+’ agak lebih rentan terhadap keadaan dan kondisi ekonomi yang memburuk dari pada debitur pada rating yang lebih tinggi. Meskipun demikian kapasitas debitur untuk memenuhi komitmen keuangannya pada obligasi masih kuat.
A9: 6 | B9: 85 | C9: 83 | D9: 6 | E9: A | F9: Good | G9: 6 | H9: 0.0004 | I9: Debitur yang diberikan rating ‘A’ agak lebih rentan terhadap keadaan dan kondisi ekonomi yang memburuk dari pada debitur pada rating yang lebih tinggi. Meskipun demikian kapasitas debitur untuk memenuhi komitmen keuangannya pada obligasi masih kuat.
A10: 7 | B10: 82 | C10: 80 | D10: 7 | E10: A- | F10: Good | G10: 7 | H10: 0.0005 | I10: Debitur yang diberikan rating ‘A-’ agak lebih rentan terhadap keadaan dan kondisi ekonomi yang memburuk dari pada debitur pada rating yang lebih tinggi. Meskipun demikian kapasitas debitur untuk memenuhi komitmen keuangannya pada obligasi masih kuat.
A11: 8 | B11: 79 | C11: 77 | D11: 8 | E11: BBB+ | F11: Average | G11: 8 | H11: 0.0018 | I11: Debitur yang mendapat rating ‘BBB+’ memperlihatkan kondisi yang memadai. Meskipun demikian kondisi ekonomi yang memburuk kemungkinan besar akan memperlemah kapasitas debitur untuk memenuhi komitmen keuangannya pada pinjamannya.
