Workbook
Name BULAN: [1]KASUS10!$I$23:$I$202
Name JKL: [2]parameter!$E$163:$E$164
Name JKW: [2]parameter!$E$190:$E$211
Name kolek: '[3]ASPEK KEU'!$K$46:$K$50
Name PENY: [2]parameter_tier!$E$141:$E$161
Name PKR: [2]parameter!$E$174:$E$177
Name PKS: [2]parameter!$E$184:$E$187
Name S1A: [2]parameter!$E$6:$E$9
Name S1B: [2]parameter!$E$11:$E$12
Name S1C: [2]parameter!$E$14:$E$17
Name S1D: [2]parameter!$E$19:$E$22
Name S2A: [2]parameter!$E$26:$E$29
Name S2B: [2]parameter!$E$31:$E$34
Name S2C: [2]parameter!$E$36:$E$39
Name S3A: [2]parameter!$E$43:$E$46
Name S3B: [2]parameter_tier!$E$48:$E$55
Name S3C: [2]parameter!$E$53:$E$55
Name S3D: [2]parameter!$E$57:$E$60
Name S3E: [2]parameter!$E$62:$E$65
Name S3F: [2]parameter!$E$67:$E$70
Name S3I: [2]parameter!$E$86:$E$89
Name S3J: [2]parameter!$E$91:$E$94
Name S3K: [2]parameter!$E$96:$E$99
Name S4A: [2]parameter!$E$103:$E$106
Name S4D: [2]parameter!$E$118:$E$121
Name S6A: [2]parameter!$E$132:$E$133
Name STA: [2]parameter!$E$180:$E$181
Name TUJ: [2]parameter!$E$159:$E$160

Sheet Informasi Pokok
A1: PROPOSAL PEMBIAYAAN
A3: Kantor (PG) | C3: : | P3: =" /BPRS-AU/"&U6&"/"&U7 -> /BPRS-AU/X/2024 | V3: 1 | W3: I
A4: Nomor Register (M) | C4: : | P4: =IF(D6="","-",#REF!) | U4: =MONTH(D6) | V4: 2 | W4: II
A5: Nomor Proposal (M) | C5: : | P5: =IF(D7="","-",P3) -> /BPRS-AU/X/2024 | U5: =MONTH(D7) | V5: 2 | W5: II
A6: Nama AO (M) | C6: : | M6: SMP | U6: =VLOOKUP(U5,V3:W17,2) | V6: 3 | W6: III
A7: Tanggal Analisa (M) | C7: : | M7: SMA | U7: =YEAR(D7) | V7: 4 | W7: IV
M8: D-3/Diploma | V8: 5 | W8: V
A9: 1. INFORMASI POKOK | M9: S1 | V9: 6 | W9: VI
M10: S-2 / S-3 | V10: 7 | W10: VII
A11: 1 | B11: Jenis Kategori Nasabah (PG) | F11: =IF(D11="Referral","Nama :","")
A12: =A11+1 | B12: Nama (M) | C12: : | V12: 8 | W12: VIII
A13: 3 | B13: Jenis Kelamin (M)
A14: 4 | B14: Tempat Lahir (M) | C14: : | G14: Tanggal Lahir : | L14: Sta Tmp Tinggal | M14: Sewa / Kontrak | V14: 9 | W14: IX
A15: 5 | B15: NIK (M) | C15: : | G15: Usia : | I15: =Parameter!E267 | M15: Orang Tua / Saudara | V15: 10 | W15: X
A16: 6 | B16: Alamat (M) | C16: : | M16: Milik Sendiri | V16: 11 | W16: XI
V17: 12 | W17: XII
D18: Desa/Kelurahan : | H18: Kecamatan :
D19: Kab./Kotamadya : | H19: Kode Pos : | L19: Jenis Usaha | M19: Pertanian
A20: =A19+1 | B20: Telpon Rumah | C20: : | M20: Industri
A21: =A16+1 | B21: HP (M) | C21: : | M21: Jasa
A22: =A21+1 | B22: Status (PG) | C22: : | M22: Perdagangan
A23: =A22+1 | B23: Jumlah Tanggungan (PG) | C23: : | M23: Lainnya (sebutkan):
A24: =A23+1 | B24: Pendidikan Terakhir (PG) | C24: :
A25: =A24+1 | B25: Nama Gadis Ibu Kandung (M) | C25: : | L25: Sistem Penj | M25: Konsinyasi / Bagi Hasil
A26: =A25+1 | B26: Nama Pasangan (Suami-Istri) (M) | C26: :
A27: =A26+1 | B27: Tempat/Tanggal Lahir (M) | C27: :
A28: =A27+1 | B28: No. KTP/SIM/Paspor (M) | C28: :
A29: =A28+1 | B29: Pekerjaan Pasangan (Suami-Istri) (M) | C29: :
A30: =A29+1 | B30: Nama Saudara Kandung Yang Dapat | C30: : | M30: Kredit & Tunai
B31: Dihubungi dan Tidak Serumah (M) | M31: Kredit
A32: =A30+1 | B32: HP (M) | C32: : | M32: Lain-lain
A34: 2. INFORMASI TEMPAT TINGGAL | L34: Lokasi Usaha | M34: Menetap/Permanen
M35: Mangkal / Non-Permanen
A36: 1 | B36: Status Tempat Tinggal (PG) | C36: : | M36: Berpindah-pindah
A37: 2 | B37: Lama Menetap (PG) | C37: : | M37: Lain-lain
A38: 3 | B38: =Parameter!B36 | C38: :
A39: 4 | B39: Indikator Reputasi di Tempat Tinggal dan Usaha (M) | C39: :
A41: 3. INFORMASI USAHA | L41: Daerah Pemasaran | M41: Sekitar Lokasi Usaha
M42: Kelurahan / Kecamatan
A43: 1 | B43: Jenis Laporan Keuangan (PG) | C43: :
...

Sheet Aspek Non Keuangan
A1: ASPEK NON KEUANGAN
A3: ASPEK MANAJEMEN
A4: a. | B4: Latar Belakang Nasabah (M) | J4: :
A13: b. | B13: Pengalaman Usaha Nasabah (M) | J13: :
A17: ASPEK TEKNIS USAHA
A18: a. | B18: Lokasi Usaha (M) | J18: :
A19: b. | B19: Gambaran Daerah Sekitar Lokasi Usaha (M) | J19: :
A23: c. | B23: Sarana & Prasarana yang dimiliki (M) | J23: :
A27: d. | B27: Perolehan / Ketersedian Bahan Baku (M) | J27: :
A31: e. | B31: Hubungan dengan Suplier (M) | J31: :
A35: f. | B35: Gambaran Singkat Proses Produksi (M) | J35: :
A40: ASPEK PEMASARAN
A41: a. | B41: Sistem Penjualan (M) | J41: :
A42: b. | B42: Daerah Pemasaran (M) | J42: :
A44: c. | B44: Saluran Distribusi (M) | J44: :
A46: d. | B46: Faktor Persaingan (M) | J46: :
A50: ASPEK LEGALITAS USAHA
A52: a. | B52: Bentuk Usaha (M) | J52: :
A54: b. | B54: Perizinan yang dimiliki
B55: JENIS | F55: NO. | M55: BERLAKU S/D | S55: ATAS NAMA
B56: NIB
B57: Sertifikat Halal
B58: SKU
A64: ASPEK LEGALITAS AGUNAN
A66: - Agunan Tanah/Bangunan
A67: No | B67: Jenis Surat/Dokumen (PG) | G67: No. | H67: Atas Nama | L67: LT2 | M67: LB2 | N67: Nilai Pasar | P67: Nilai | Q67: Os. Pokok | R67: Nilai Bank (O) | V67: Peng-ikatan (PG) | X67: Lokasi Agunan (M)
N68: KJPP/Internal (M) | P68: Agunan % (M) | Q68: Paripasu (M)
A69: 1 | R69: =(N69*P69)-Q69
A70: =A69+1 | R70: =(N70*P70)-Q70
A71: =A70+1 | R71: =(N71*P71)-Q71
A72: =A71+1 | R72: =(N72*P72)-Q72
A73: =A72+1 | R73: =(N73*P73)-Q73
A74: =A73+1 | R74: =(N74*P74)-Q74
A75: =A74+1 | R75: =(N75*P75)-Q75
A76: Total (O) | N76: =SUM(N69:O75) | R76: =SUM(R69:U75)
A78: - Agunan Kendaraan Bermotor
A79: No | B79: BPKB-Merek | E79: Type | H79: Thn | I79: Atas Nama | L79: No. BPKB | N79: Nopol | O79: Nilai Pasar | Q79: Nilai | R79: Os. Pokok | V79: Nilai Bank | Z79: Peng-ikatan
O80: KJPP/Internal | Q80: Agunan % (M) | R80: Paripasu (M)
A81: 1 | V81: =(O81*Q81)-R81
A82: 2 | V82: =(O82*Q82)-R82
...

Sheet AKTIVITAS USAHA
A1: URAIAN AKTIVITAS USAHA DEBITUR/CALON DEBITUR
A3: ASPEK PEMASARAN
A4: A. | B4: TINGKAT PERMINTAAN
B5: Performance Indicator | H5: Uraian Singkat
B6: Ukuran target pasar (market size) | H6: Tingkat konsumsi tinggi, daya beli tinggi
B8: Luas area geografis target pasar. | H8: Regional
B10: Pola/sifat permintaan target pasar | H10: stabil
B12: Pertumbuhan permintaan target pasar | H12: Diperkirakan 0% s/d 5%
B14: Pangsa Pasar Perusahaan | H14: Diperkirakan 20 besar
B15: Diversifikasi segmen pasar perusahaan | H15: 5 segmen atau lebih
B17: Realisasi penjualan dibanding target | H17: Penjualan kurang dari 50% target
A20: B. | B20: KUALITAS PRODUK ATAU JASA
B21: Performance Indicator | H21: Uraian Singkat
B22: Kualitas produk/jasa | H22: ◊ | I22: Reliabilitas/Keandalan
H26: ◊ | I26: Jaminan Kepastian
H30: ◊ | I30: Pelayanan
I31: Produk yang ditawarkan cukup dikenal oleh masyarakat, dan tetap digunakan di setiap waktu.
H34: ◊ | I34: Empati
I35: Kebutuhan pelanggan terhadap produk tsb tetap dipertahankan. Apabila pelanggan mengeluh, pemohon mengantisipasi dengan cepat. Hal ini terlihat banyaknya pelanggan pemohon.
H38: ◊ | I38: Responsif
I39: Pemohon mampu memberikan pelayanan dan pengiriman yang cepat kepada pelanggannya. Hal ini terlihat dari jumlah alat transportasi yang digunakan oleh pemohon.
B43: Tingkat harga produk/jasa | H43: Di bawah harga pasar.
B45: Rentang jenis produk (diversifikasi produk)
B49: Kekuatan merk (brand image) | H49: Untuk produk yang ditawarkan oleh pemohon beberapa produk telah cukup dikenal oleh para pelanggannya. Hal ini terlihat dari jumlah penjualan setiap harinya.
B53: Inovasi produk/jasa
B57: Jaringan distribusi | H57: Di atas 15 cabang/ outlet/agen/sales forces
B59: Syarat-syarat penjualan | H59: Syarat-syarat penjualan yang dilakukan pemohon antara lain:
I63: - | J63: Pemohon lebih mengutamakan pembayaran tunai
I64: - | J64: Untuk pembayaran kredit diperbolehkan dengan masa 1-2 hari
I65: - | J65: Penjualan ditargetkan sebanyak +/-50%
I66: -
A68: C. | B68: KONSENTRASI PELANGGAN
B69: Performance Indicator | H69: Uraian Singkat
B70: Proporsi penjualan per pelanggan | H70: 4 pelanggan menguasai 15% penjualan atau lebih
B72: Kualitas hubungan dengan pelanggan | H72: Hubungan antara pemohon dengan para pelanggannya telah terjalin baik hal ini terlihat antara lain:
I75: - | J75: Lamanya hubungan dengan pelanggan
I76: - | J76: Track record penyelesaian hak-kewajiban pelanggan
I77: - | J77: Untuk di wilayah tsb pemohon telah dikenal baik oleh para pelanggannya
B79: Daya tawar pelanggan | H79: Tawar menawar antara pelanggan dengan pemohon cukup baik. Hal ini terlihat dari beberapa faktor antara lain:
I82: - | J82: Planggan mengutamakan harga yang murah, hingga pelanggan
...

Sheet Rekening Koran & Aset 
A1: BANK (M): | D1: Currency (M): | E1: IDR | G1: ='[4]Informasi Pokok'!D5
A2: Nomor Rekening (M): | D2: Saldo Awal (M): | G2: 1
A3: Atas Nama (M): | C3: ='Informasi Pokok'!D12
A5: Bulan | B5: Mutasi Debet | C5: Mutasi Kredit | D5: Saldo | E5: Bulan | F5: Mutasi Debet | G5: Mutasi Kredit | H5: Saldo | I5: Bulan | J5: Mutasi Debet | K5: Mutasi Kredit | L5: Saldo
D6: =E2 | E6: =IF(A6="","",DATE(YEAR(A6),MONTH(A6)+1,DAY(A6))) | H6: =D53 | I6: =IF(E6="","",DATE(YEAR(E6),MONTH(E6)+1,DAY(E6))) | L6: =H53 | M6: Bulan | N6: FQ | O6: Debet | P6: Rata2 Transaksi | Q6: FQ | R6: Kredit | S6: Rata2 Transaksi | T6: Saldo Akhir
A7: =$A$6 | D7: =D6-B7+C7 | E7: =$E$6 | H7: =H6-F7+G7 | I7: =$I$6 | L7: =L6-J7+K7 | M7: =A6 | N7: =B57 | O7: =B55 | P7: =B56 | Q7: =C57 | R7: =C55 | S7: =C56 | T7: =D53
A8: =$A$6 | D8: =D7-B8+C8 | E8: =$E$6 | H8: =H7-F8+G8 | I8: =$I$6 | L8: =L7-J8+K8 | M8: =E6 | N8: =F57 | O8: =F55 | P8: =F56 | Q8: =G57 | R8: =G55 | S8: =G56 | T8: =H53
A9: =$A$6 | D9: =D8-B9+C9 | E9: =$E$6 | H9: =H8-F9+G9 | I9: =$I$6 | L9: =L8-J9+K9 | M9: =I6 | N9: =J57 | O9: =J55 | P9: =J56 | Q9: =K57 | R9: =K55 | S9: =K56 | T9: =D67
A10: =$A$6 | D10: =D9-B10+C10 | E10: =$E$6 | H10: =H9-F10+G10 | I10: =$I$6 | L10: =L9-J10+K10 | M10: Rata-rata | N10: =AVERAGE(N7:N9) | O10: =AVERAGE(O7:O9) | P10: =AVERAGE(P7:P9) | Q10: =AVERAGE(Q7:Q9) | R10: =AVERAGE(R7:R9) | S10: =AVERAGE(S7:S9) | T10: =AVERAGE(T7:T9)
A11: =$A$6 | D11: =D10-B11+C11 | E11: =$E$6 | H11: =H10-F11+G11 | I11: =$I$6 | L11: =L10-J11+K11
A12: =$A$6 | D12: =D11-B12+C12 | E12: =$E$6 | H12: =H11-F12+G12 | I12: =$I$6 | L12: =L11-J12+K12
A13: =$A$6 | D13: =D12-B13+C13 | E13: =$E$6 | H13: =H12-F13+G13 | I13: =$I$6 | L13: =L12-J13+K13
A14: =$A$6 | D14: =D13-B14+C14 | E14: =$E$6 | H14: =H13-F14+G14 | I14: =$I$6 | L14: =L13-J14+K14
A15: =$A$6 | D15: =D14-B15+C15 | E15: =$E$6 | H15: =H14-F15+G15 | I15: =$I$6 | L15: =L14-J15+K15
A16: =$A$6 | D16: =D15-B16+C16 | E16: =$E$6 | H16: =H15-F16+G16 | I16: =$I$6 | L16: =L15-J16+K16
A17: =$A$6 | D17: =D16-B17+C17 | E17: =$E$6 | H17: =H16-F17+G17 | I17: =$I$6 | L17: =L16-J17+K17
A18: =$A$6 | D18: =D17-B18+C18 | E18: =$E$6 | H18: =H17-F18+G18 | I18: =$I$6 | L18: =L17-J18+K18
A19: =$A$6 | D19: =D18-B19+C19 | E19: =$E$6 | H19: =H18-F19+G19 | I19: =$I$6 | L19: =L18-J19+K19
A20: =$A$6 | D20: =D19-B20+C20 | E20: =$E$6 | H20: =H19-F20+G20 | I20: =$I$6 | L20: =L19-J20+K20
A21: =$A$6 | D21: =D20-B21+C21 | E21: =$E$6 | H21: =H20-F21+G21 | I21: =$I$6 | L21: =L20-J21+K21
A22: =$A$6 | D22: =D21-B22+C22 | E22: =$E$6 | H22: =H21-F22+G22 | I22: =$I$6 | L22: =L21-J22+K22
... A53: =$A$6 | D53: =D52-B53+C53 | E53: =$E$6 | H53: =H52-F53+G53 | I53: =$I$6 | L53: =L52-J53+K53
A55: Total | B55: =SUM(B6:B53) | C55: =SUM(C6:C53) | E55: Total | F55: =SUM(F6:F53) | G55: =SUM(G6:G53) | I55: Total | J55: =SUM(J6:J53) | K55: =SUM(K6:K53)
A56: Average | B56: =AVERAGE(B6:B53) | C56: =AVERAGE(C6:C53) | E56: Average | F56: =AVERAGE(F6:F53) | G56: =AVERAGE(G6:G53) | I56: Average | J56: =AVERAGE(J6:J53) | K56: =AVERAGE(K6:K53)
A57: FQ | B57: =COUNTIF(B6:B53,">0") | C57: =COUNTIF(C6:C53,">0") | E57: FQ | F57: =COUNTIF(F6:F53,">0") | G57: =COUNTIF(G6:G53,">0") | I57: FQ | J57: =COUNTIF(J6:J53,">0") | K57: =COUNTIF(K6:K53,">0")
A59: SALDO BANK LAIN
A60: Bulan | B60: Nama BANK | C60: No. Rekening | D60: Saldo
A61: =I53 | B61: =C1 | C61: =C2 | D61: =L53
A62: =A61 | B62: A
A63: =A62 | B63: B
A64: =A63 | B64: C
A65: =A64 | B65: D
A66: =A65 | B66: E
A67: Total | D67: =SUM(D61:D66)
B83: ASSET YANG DIMILIKI
B85: ASSET PRIBADI | F85: ASSET PRIBADI
B87: Jenis Asset (M) | D87: Tanah&Bangunan | F87: Jenis Asset (M) | H87: Saldo Bank
B88: Tahun Perolehan (M) | F88: Tahun Perolehan (M) | H88: =C1
B89: Nilai Taksasi Bank (M) | F89: Nilai Taksasi Bank (M) | H89: =T9
B90: Jenis Asset (M) | D90: Tanah&Bangunan | F90: Jenis Asset (M) | H90: Tanah&Bangunan
...

Sheet Aspek Keuangan
A1: ANALISA KEUANGAN
A3: 1. KAS DAN BANK
A5: Kas (M) | F5: :
B7: BULAN | E7: FQ | F7: DEBET | I7: RATA2 | L7: FQ | M7: KREDIT | P7: RATA2 | S7: SALDO AKHIR | V7: * | W7: =Parameter!B103
B8: ='Rekening Koran & Aset '!M7 | E8: ='Rekening Koran & Aset '!N7 | F8: ='Rekening Koran & Aset '!O7 | I8: ='Rekening Koran & Aset '!P7 | L8: ='Rekening Koran & Aset '!Q7 | M8: ='Rekening Koran & Aset '!R7 | P8: ='Rekening Koran & Aset '!S7 | S8: ='Rekening Koran & Aset '!T7 | W8: =IF(L11<1,"Tidak ada",IF(L11<3,"Pasif atau kurang dari 3 kali perbulan",IF(AND(L11>=3,L11<=8),"Mutasi 3 - 8 kali perbulan",IF(L11>8,"Lebih dari 8 kali perbulan"))))
B9: ='Rekening Koran & Aset '!M8 | E9: ='Rekening Koran & Aset '!N8 | F9: ='Rekening Koran & Aset '!O8 | I9: ='Rekening Koran & Aset '!P8 | L9: ='Rekening Koran & Aset '!Q8 | M9: ='Rekening Koran & Aset '!R8 | P9: ='Rekening Koran & Aset '!S8 | S9: ='Rekening Koran & Aset '!T8 | V9: * | W9: =Parameter!B98 -> Saldo rekening rata-rata per-bulan
B10: ='Rekening Koran & Aset '!M9 | E10: ='Rekening Koran & Aset '!N9 | F10: ='Rekening Koran & Aset '!O9 | I10: ='Rekening Koran & Aset '!P9 | L10: ='Rekening Koran & Aset '!Q9 | M10: ='Rekening Koran & Aset '!R9 | P10: ='Rekening Koran & Aset '!S9 | S10: ='Rekening Koran & Aset '!T9 | W10: =IF(S11<1,"Tidak ada",IF(S11<5000000,"< 5 Juta",IF(AND(S11>=5000000,S11<=10000000),"5 - 10 juta",IF(S11>10000000,"> 10 juta"))))
B11: ='Rekening Koran & Aset '!M10 | E11: ='Rekening Koran & Aset '!N10 | F11: ='Rekening Koran & Aset '!O10 | I11: ='Rekening Koran & Aset '!P10 | L11: ='Rekening Koran & Aset '!Q10 | M11: ='Rekening Koran & Aset '!R10 | P11: ='Rekening Koran & Aset '!S10 | S11: ='Rekening Koran & Aset '!T10
A14: Total Kas dan Bank (O) | F14: : | G14: =G5+S10
A16: 2. PIUTANG USAHA
A18: NO | B18: NAMA (M) | H18: JUMLAH (M) | K18: HARGA (M) | O18: TOTAL (O) | T18: KETERANGAN: LAMA PIUTANG <=12 Bulan
A19: 1 | O19: =H19*K19
A20: 2
A21: 3
A22: 4
A23: 5
A24: TOTAL | H24: =SUM(H19:J23) | K24: =SUM(K19:N23) | O24: =SUM(O19:S23)
A26: Keterangan :
A29: 3. PERSEDIAAN
A31: NO | B31: NAMA BARANG (M) | H31: JUMLAH (M) | K31: SATUAN (M) | N31: HARGA (M) | R31: TOTAL HARGA (O)
A32: 1 | R32: =H32*N32
A33: 2 | R33: =H33*N33
A34: 3 | R34: =H34*N34
A35: 4 | R35: =H35*N35
A36: 5 | R36: =H36*N36
A37: TOTAL | N37: =SUM(N32:Q36) | R37: =SUM(R32:V36)
A39: Keterangan :
A42: 4. HUTANG USAHA
A44: NO | B44: NAMA (M) | H44: JUMLAH (M) | K44: HARGA (M) | O44: TOTAL (O) | T44: KETERANGAN
A45: 1 | O45: =H45*K45
A46: 2 | O46: =H46*K46
A47: 3 | O47: =H47*K47
A48: TOTAL | H48: =SUM(H45:J47) | K48: =SUM(K45:N47) | O48: =SUM(O45:S47)
A50: Keterangan :
A53: 5. HUBUNGAN BANK
A54: Calon Nasabah
A55: NO | B55: NAMA BANK (M) | F55: PLAFOND (M) | I55: BAKI DEBET (O) | L55: MARGIN/TH (M) | N55: ANGSURAN/BLN (O) | Q55: TGL MULAI (M) | T55: TGL AKHIR (M) | W55: PANGSA (M) | Y55: % (PG) | Z55: KOL (M) | AA55: DILUNASI (PG)
A56: 1 | I56: =IF(Y56="Flat",AP56,AO56) | N56: =IF(AA56="Ya",0,AE56) | Y56: Flat | AA56: Tidak | AD56: Ya | AE56: =IF(Y56="Flat",AI56,AK56) | AF56: =IF(AA56="Ya",AP56,0) | AG56: =IF(AA56="Ya",B56,"") | AH56: =DATEDIF(Q56,T56,"M") | AI56: =IFERROR(F56/Parameter!D269,"0")+IFERROR(F56*(L56/12),"") | AJ56: =PMT(L56/12,AH56,-F56) | AK56: =IFERROR(AJ56,0) | AL56: =Parameter!F269 | AM56: =(AH56/12)*L56 | AN56: =F56*(1+AM56/AH56)^AL56-(AK56*((1+AM56/AH56)^AL56-1)/(AM56/AH56)) | AO56: =IFERROR(AN56,0) | AP56: =IFERROR(Parameter!G269*Parameter!G270,"")
A57: 2 | I57: =IF(Y57="Flat",AP57,AO57) | N57: =IF(AA57="Ya",0,AE57) | AD57: Tidak | AE57: =IF(Y57="Flat",AI57,AK57) | AF57: =IF(AA57="Ya",AP57,0) | AG57: =IF(AA57="Ya",B57,"") | AH57: =DATEDIF(Q57,T57,"M") | AI57: =IFERROR(F57/Parameter!D271,"0")+IFERROR(F57*(L57/12),"") | AJ57: =PMT(L57/12,AH57,-F57) | AK57: =IFERROR(AJ57,0) | AL57: =Parameter!F271 | AM57: =(AH57/12)*L57 | AN57: =F57*(1+AM57/AH57)^AL57-(AK57*((1+AM57/AH57)^AL57-1)/(AM57/AH57)) | AO57: =IFERROR(AN57,0) | AP57: =IFERROR(Parameter!G271*Parameter!G272,"")
A58: 3 | I58: =IF(Y58="Flat",AP58,AO58) | N58: =IF(AA58="Ya",0,AE58) | AE58: =IF(Y58="Flat",AI58,AK58) | AF58: =IF(AA58="Ya",AP58,0) | AG58: =IF(AA58="Ya",B58,"") | AH58: =DATEDIF(Q58,T58,"M") | AI58: =IFERROR(F58/Parameter!D273,"0")+IFERROR(F58*(L58/12),"") | AJ58: =PMT(L58/12,AH58,-F58) | AK58: =IFERROR(AJ58,0) | AL58: =Parameter!F273 | AM58: =(AH58/12)*L58 | AN58: =F58*(1+AM58/AH58)^AL58-(AK58*((1+AM58/AH58)^AL58-1)/(AM58/AH58)) | AO58: =IFERROR(AN58,0) | AP58: =IFERROR(Parameter!G273*Parameter!G274,"")
...

Sheet Usulan Pembiayaan
A2: PROPOSAL USULAN PEMBIAYAAN | AA2: kdprd | AB2: prd
B3: Nomor Proposal | F3: : | G3: ='Informasi Pokok'!D5 | AA3: 10 | AB3: Murabahah | AC3: Harga Pokok | AD3: Margin | AE3: Harga Jual | AF3: Harga Pokok Barang | AG3: Urbun/Uang Muka I | AH3: Urbun/Uang Muka II | AI3: ---∞∞∞∞∞¶¶¶¶¶∞∞∞∞∞--- | AJ3: Pembiayaan Bank | AK3: Angsuran Margin/Bulan | AL3: Expected Return/Bulan | AM3: Angsuran Pokok/Bulan | AN3: Total Angsuran/Bulan | AO3: =$J$76-$J$77-$J$78 | AP3: Surplus/Minus Cashflow
B4: Tanggal Usulan | F4: : | G4: =TODAY() | AA4: 11 | AB4: PKE | AC4: Harga Pokok | AD4: Margin | AE4: Harga Jual | AF4: Harga Pokok Barang | AG4: Urbun/Uang Muka I | AH4: Urbun/Uang Muka II | AI4: ---∞∞∞∞∞¶¶¶¶¶∞∞∞∞∞--- | AJ4: Pembiayaan Bank | AK4: Angsuran Margin/Bulan | AL4: Expected Return/Bulan | AM4: Angsuran Pokok/Bulan | AN4: Total Angsuran/Bulan | AO4: =$J$76-$J$77-$J$78 | AP4: Surplus/Minus Cashflow
B5: Dari | F5: : | G5: Account Officer | AA5: 20 | AB5: Istishna | AC5: Harga Pokok | AD5: Margin | AE5: Harga Jual | AF5: Harga Pokok Barang | AG5: Urbun/Uang Muka I | AH5: Urbun/Uang Muka II | AI5: ---∞∞∞∞∞¶¶¶¶¶∞∞∞∞∞--- | AJ5: Pembiayaan Bank | AK5: Angsuran Margin/Bulan | AL5: Expected Return/Bulan | AM5: Angsuran Pokok/Bulan | AN5: Total Angsuran/Bulan | AO5: =$J$76-$J$77-$J$78 | AP5: Surplus/Minus Cashflow
B6: Kepada | F6: : | G6: Komite Pemutus Pembiayaan (KMPP) | AA6: 30 | AB6: Salam | AC6: Harga Pokok | AD6: Margin | AE6: Harga Jual | AF6: Harga Pokok Barang | AG6: Urbun/Uang Muka I | AH6: Urbun/Uang Muka II | AI6: ---∞∞∞∞∞¶¶¶¶¶∞∞∞∞∞--- | AJ6: Pembiayaan Bank | AK6: Angsuran Margin/Bulan | AL6: Expected Return/Bulan | AM6: Angsuran Pokok/Bulan | AN6: Total Angsuran/Bulan | AO6: =$J$76-$J$77-$J$78 | AP6: Surplus/Minus Cashflow
B7: Perihal | F7: : | G7: ="Permohonan Pembiayaan atas nama "&N14 | AA7: 50 | AB7: Ijarah | AC7: Harga Pokok Sewa | AD7: Ujroh | AE7: Harga Jual Sewa | AF7: Harga Pokok sewa | AG7: Urbun/Uang Muka I | AH7: Urbun/Uang Muka II | AI7: ---∞∞∞∞∞¶¶¶¶¶∞∞∞∞∞--- | AJ7: Pembiayaan Bank | AK7: Ujroh Sewa/Bulan | AL7: Ujroh Sewa (Setara)/Bulan | AM7: Angsuran Pokok Sewa/Bulan | AN7: Total Angsuran Sewa/Bln | AO7: =$J$76-$J$77-$J$78 | AP7: Surplus/Minus Cashflow
AA8: 51 | AB8: Ijarah Multijasa | AC8: Harga Pokok Sewa | AD8: Ujroh | AE8: Harga Jual Sewa | AF8: Harga Pokok sewa | AG8: Urbun/Uang Muka I | AH8: Urbun/Uang Muka II | AI8: ---∞∞∞∞∞¶¶¶¶¶∞∞∞∞∞--- | AJ8: Pembiayaan Bank | AK8: Ujroh Sewa/Bulan | AL8: Ujroh Sewa (Setara)/Bulan | AM8: Angsuran Pokok Sewa/Bulan | AN8: Total Angsuran Sewa/Bln | AO8: =$J$76-$J$77-$J$78 | AP8: Surplus/Minus Cashflow
B9: Bismillahhirahmannirrahim | AA9: 70 | AB9: Mudharabah | AC9: Pokok | AD9: Proyeksi Bagi Hasil | AE9: Total | AF9: Nilai Proyek | AG9: Modal Nasabah | AH9: Modal Bank | AI9: ---∞∞∞∞∞¶¶¶¶¶∞∞∞∞∞--- | AJ9: Pembiayaan Bank | AK9: Proyeksi Bagi Hasil/Bulan | AL9: Expected Return/Bulan | AM9: Proyeksi Angsuran Pokok/Bulan | AN9: Proyeksi Angsuran Pokok&Bagas/Bln | AO9: =$J$76-$J$77 | AP9: Proyeksi Surplus/Minus Cashflow
B10: ="Kami sampaikan Memorandum Usulan Pembiayaan atas nama "&N14&" dengan hal-hal sebagai berikut:" | AA10: 60 | AB10: Musyarakah | AC10: Pokok | AD10: Proyeksi Bagi Hasil | AE10: Total | AF10: Nilai Proyek | AG10: Modal Nasabah | AH10: Modal Bank | AI10: ---∞∞∞∞∞¶¶¶¶¶∞∞∞∞∞--- | AJ10: Pembiayaan Bank | AK10: Proyeksi Bagi Hasil/Bulan | AL10: Expected Return/Bulan | AM10: Proyeksi Angsuran Pokok/Bulan | AN10: Proyeksi Angsuran Pokok&Bagas/Bln | AO10: =$J$76-$J$77 | AP10: Proyeksi Surplus/Minus Cashflow
AA11: 65 | AB11: MMQ RS | AC11: Pokok (Hishah) | AD11: Bagi Hasil Atas Sewa | AE11: Harga Jual Sewa | AF11: Harga Pasar Aset | AG11: Harga Aset yang Dibeli Bank dari Nas. | AH11: Kepemilikan Aset Bank (Hishah) | AI11: Kepemilikan Aset Nasabah (Hishah) | AJ11: Harga Aset yang Disewa Nasabah | AK11: Ujroh Sewa/Bulan | AL11: Ujroh Sewa (Setara)/Bulan | AM11: Penebusan Aset/Hishah Oleh Nas. | AN11: Total Angsuran Sewa/Bln | AO11: =J76-J79 | AP11: Surplus/Minus Cashflow
A12: PERMOHONAN YANG DIAJUKAN | AA12: 52 | AB12: IMBT RS | AC12: Harga Pokok Sewa | AD12: Ujroh | AE12: Harga Jual Sewa | AF12: Harga Pasar Aset | AG12: Harga Aset yang Dibeli Bank dari Nas. | AH12: ---∞∞∞∞∞¶¶¶¶¶∞∞∞∞∞--- | AI12: ---∞∞∞∞∞¶¶¶¶¶∞∞∞∞∞--- | AJ12: Harga Aset yang Disewa Nasabah | AK12: Ujroh Sewa/Bulan | AL12: Ujroh Sewa (Setara)/Bulan | AM12: Angsuran Pokok Sewa/Bulan | AN12: Total Angsuran Sewa/Bln | AO12: =J77 | AP12: Surplus/Minus Cashflow
AA13: 40 | AB13: Qardh | AC13: Pokok | AD13: ---∞∞∞∞∞¶¶¶¶¶∞∞∞∞∞--- | AE13: ---∞∞∞∞∞¶¶¶¶¶∞∞∞∞∞--- | AF13: ---∞∞∞∞∞¶¶¶¶¶∞∞∞∞∞--- | AG13: ---∞∞∞∞∞¶¶¶¶¶∞∞∞∞∞--- | AH13: ---∞∞∞∞∞¶¶¶¶¶∞∞∞∞∞--- | AI13: ---∞∞∞∞∞¶¶¶¶¶∞∞∞∞∞--- | AJ13: Pembiayaan Bank | AK13: - | AL13: - | AM13: Angsuran Pokok | AN13: Total Angsuran/Bulan | AO13: =J76 | AP13: Surplus/Minus Cashflow
A14: 1 | B14: Nama Pemohon | L14: : | N14: ='Informasi Pokok'!D12
A15: 2 | B15: Akad Pembiayaan | L15: : | N15: ='Informasi Pokok'!D67
A16: 3 | B16: Jenis Penggunaan | L16: : | N16: ='Informasi Pokok'!D69
A17: 4 | B17: Jumlah Permohonan | L17: : | N17: ='Informasi Pokok'!D64
A18: 5 | B18: Expected Return/Bulan | L18: : | N18: ='Informasi Pokok'!D66 | R18: ='Informasi Pokok'!E66
A19: 6 | B19: Jangka Waktu | L19: : | N19: ='Informasi Pokok'!D65 | R19: Bulan | AB19: ='Informasi Pokok'!D67 | AC19: =VLOOKUP($AB$19,$AB$3:$AO$15,2,0) | AD19: =VLOOKUP($AB$19,$AB$3:$AO$15,3,0) | AE19: =VLOOKUP($AB$19,$AB$3:$AO$15,4,0) | AF19: =VLOOKUP($AB$19,$AB$3:$AO$15,5,0) | AG19: =VLOOKUP($AB$19,$AB$3:$AO$15,6,0) | AH19: =VLOOKUP($AB$19,$AB$3:$AO$15,7,0) | AI19: =VLOOKUP($AB$19,$AB$3:$AO$15,8,0) | AJ19: =VLOOKUP($AB$19,$AB$3:$AO$15,9,0) | AK19: =VLOOKUP($AB$19,$AB$3:$AO$15,10,0) | AL19: =VLOOKUP($AB$19,$AB$3:$AO$15,11,0) | AM19: =VLOOKUP($AB$19,$AB$3:$AO$15,12,0) | AN19: =VLOOKUP($AB$19,$AB$3:$AO$15,13,0) | AO19: =VLOOKUP($AB$19,$AB$3:$AO$15,14,0) | AP19: =VLOOKUP($AB$19,$AB$3:$AP$13,15,0)
A20: 7 | B20: Angsuran Perbulan | L20: : | N20: =IF(R18="Flat",AB20,AC20) | AB20: =(N17*N18*N19+N17)/N19 | AC20: =PMT(N18,N19,-N17)
A24: ANALISA KEUANGAN
A26: 1 | B26: Penjualan Perbulan | L26: : | M26: Rp. | N26: ='Aspek Keuangan'!L102 | AA26: 1 | AB26: min | AC26: mid
A27: 2 | B27: Harga Pokok Pembelian (HPP) | L27: : | M27: Rp. | N27: ='Aspek Keuangan'!P102 | AA27: 0.7 | AB27: RPC <1.43 | AC27: RPC 1.43 sd. 4.50 | AD27: RPC >4.50 sd. 6.50 | AE27: RPC >6.50
A28: 3 | B28: Laba Kotor | L28: : | M28: Rp. | N28: =N26-N27 | AA28: 0.75 | AB28: RPC <1.33 | AC28: RPC 1.33 sd. 3.25 | AD28: RPC >3.25 sd. 6.25 | AE28: RPC >6.25
A29: 4 | B29: Biaya Operasional | AA29: 0.8 | AB29: RPC <1.25 | AC29: RPC 1.25 sd. 3 | AD29: RPC >3 sd. 5 | AE29: RPC >5
B30: - | C30: Biaya Tenaga Kerja | L30: : | M30: Rp. | N30: ='Aspek Keuangan'!M119 | AA30: =N39 | AB30: =AA26/AA30
B31: - | C31: Biaya Usaha | L31: : | M31: Rp. | N31: ='Aspek Keuangan'!M129
B32: - | C32: Biaya Rumah Tangga | L32: : | M32: Rp. | N32: ='Aspek Keuangan'!M140 | AA32: =B105 | AB32: =VLOOKUP(AA30,AA26:AE29,3,0)
A33: 5 | B33: Laba Sebelum Pajak | L33: : | M33: Rp. | N33: =N28-N30-N31-N32 | AE33: RPC <1.25
A34: 6 | B34: Taksiran Pajak | L34: : | M34: Rp. | N34: =N33*5% | AA34: 0.8 | AB34: =IF($AA$61<2.5,"RPC <2.50",IF(AND($AA$61>=2.5,$AA$61<=4),"RPC 2.50 sd. 4",IF(AND($AA$61>4,$AA$61<=6),"RPC >4 sd. 6",IF($AA$61>6,"RPC >6")))) | AC34: =IF($AA$32<1.25,AB29,IF(AND($AA$32>=1.25,$AA$32<=3),AC29,IF(AND($AA$32>3,$AA$32<=5),AD29,IF($AA$32>5,AE29)))) | AE34: RPC 1.25 s.d 3
A35: 7 | B35: Laba Bersih Usaha | L35: : | M35: Rp. | N35: =N33-N34 | AA35: 0.75 | AB35: =IF($AA$61<2.86,"RPC <2.86",IF(AND($AA$61>=2.86,$AA$61<=4.25),"RPC 2.86 sd. 4.25",IF(AND($AA$61>4.25,$AA$61<=6.5),"RPC >4.25 sd. 6.50",IF($AA$61>6.5,"RPC >6.50")))) | AC35: =IF($AA$32<1.33,AB28,IF(AND($AA$32>=1.33,$AA$32<=3.25),AC28,IF(AND($AA$32>3.25,$AA$32<=6.25),AD28,IF($AA$32>6.25,AE28)))) | AE35: RPC >3 s.d 5
A36: 8 | B36: %Repayment Capacity (RPC-NPM) | L36: : | AA36: 0.7 | AB36: =IF($AA$61<3.33,"RPC <3.33",IF(AND($AA$61>=3.33,$AA$61<=4.5),"RPC 3.33 sd. 4.50",IF(AND($AA$61>4.5,$AA$61<=6.5),"RPC >4 sd. 6.50",IF($AA$61>6.5,"RPC >6.50")))) | AC36: =IF($AA$32<1.43,AB27,IF(AND($AA$32>=1.43,$AA$32<=4.5),AC27,IF(AND($AA$32>4.5,$AA$32<=6.5),AD27,IF($AA$32>6.5,AE27)))) | AE36: RPC > 5
A37: 9 | B37: Repayment Capacity (RPC) | L37: : | M37: Rp. | N37: =N35*N36
A38: 10 | B38: Pendapatan Lain-Biaya Lain | L38: : | M38: Rp. | N38: ='Aspek Keuangan'!T152-'Aspek Keuangan'!T147 | AA38: =VLOOKUP(AA30,AA34:AC36,3,0) | AB38: =VLOOKUP($AA$30,$AA$27:$AE$29,2,0) | AC38: 1
A39: 11 | B39: Angsuran BANK | L39: : | M39: Rp. | N39: ='Aspek Keuangan'!N61+'Aspek Keuangan'!N72 | AB39: =VLOOKUP($AA$30,$AA$27:$AE$29,3,0) | AC39: 5
A41: 12 | B41: Potensi Besarnya Angsuran | L41: : | M41: Rp. | N41: =(N37+N38)-N39 | AB41: =VLOOKUP($AA$30,$AA$27:$AE$29,4,0) | AC41: 7
A42: 13 | B42: Kebutuhan Pembiayaan Modal Kerja, Investasi&Konsumtif- RPC | L42: : | M42: Rp. | N42: =(N41*J81)/(1+(J81*J82)) | AB42: =VLOOKUP($AA$30,$AA$27:$AE$29,5,0) | AC42: 10
A43: 14 | B43: Kebutuhan Modal Usaha Saat Ini
B45: Perputaran Persediaan | I45: : | J45: ='Aspek Keuangan'!R37*30/'Aspek Keuangan'!L102 | L45: hari | AD45: =VLOOKUP(AA38,AB38:AC42,2,0)
B46: Perputaran Piutang | I46: : | J46: ='Aspek Keuangan'!O24*30/'Aspek Keuangan'!L102 | L46: hari
B47: Perputaran Hutang | I47: : | J47: ='Aspek Keuangan'!O48*30/'Aspek Keuangan'!L102 | L47: hari
...

Sheet K Modal
B2: PERPUTARAN MODAL KERJA
Y3: Kebutuhan Modal Kerja | AB3: Kebutuhan Modal Kerja Berdasakan Perputaran Usaha
B4: Perputaran Kas | H4: : | I4: Δ | J4: Penjualan | M4: = | N4: ='Usulan Pembiayaan'!N26:Q26 | S4: = | T4: =N4/N5 | V4: kali | Y4: Tranding Asset | Z4: =+N17+N11 | AB4: Perputaran Persediaan | AC4: =+N17*30/N4
J5: Kas | N5: ='Aspek Keuangan'!G14 | Y5: SF | Z5: ='Aspek Keuangan'!O48 | AB5: Perputaran Piutang | AC5: =+N11*30/N4
Y6: Kebutuhan Modal | Z6: =+Z4-Z5 | AB6: Perputaran Utang | AC6: =('Aspek Keuangan'!O48+200000000)*30/N4
I7: Δ | J7: HARI | L7: = | M7: 30 | O7: = | P7: =M7/M8 | R7: hari | Y7: PM 15% | Z7: ='Aspek Keuangan'!O102*Z6 | AB7: NTC | AC7: =+(AC4+AC5)-AC6
M8: =T4 | Y8: Kebutuhan Modal Kerja Netto | Z8: =+Z6-Z7 | AB8: Kebutuhan Modal Kerja Netto | AC8: =((1-(100%-85%))*((N4*AC7)/30))
Y9: 1.1 | Z9: =Z8*Y9 | AC9: =S34-AC8
B10: Perputaran Piutang | H10: : | I10: Δ | J10: Penjualan | M10: = | N10: =N4 | S10: = | T10: =N10/N11 | V10: kali | AC10: =AC9/S34
J11: Piutang | N11: ='Aspek Keuangan'!O24
I13: Δ | J13: HARI | L13: = | M13: 30 | O13: = | P13: =M13/M14 | R13: hari
M14: =T10 | Y14: =N4*85%
B16: Perputaran Persediaan | H16: : | I16: Δ | J16: HPP | M16: = | N16: =Y14 | S16: = | T16: =N16/N17 | V16: kali
J17: Persediaan | N17: ='Aspek Keuangan'!R37
I19: Δ | J19: HARI | L19: = | M19: 30 | O19: = | P19: =M19/M20 | R19: hari
M20: =T16
B23: Proyeksi Kas | G23: : | H23: =P7 | J23: X | K23: =N4 | O23: X | P23: 1 | R23: = | S23: =(H23*K23/H24)*P23
H24: 30
B26: Proyeksi Piutang | G26: : | H26: =P13 | J26: X | K26: =N10 | O26: X | P26: 1.2 | R26: = | S26: =(K26*H26/H27)*P26
H27: 30
B29: Proyeksi Persediaan | G29: : | H29: =P19 | J29: X | K29: =N16 | O29: X | P29: 1.2 | R29: = | S29: =(K29*H29/H30)*P29
H30: 30
B32: Jumlah Proyeksi Modal kerja | S32: =S23+S26+S29
B34: Modal Kerja Bersih | S34: =N17+N11+N5 | W34: (-)
S35: =S32-S34
B36: Kebutuhan Kredit
B38: Hutang Dagang
B40: Hutang Bank | L40: (+)
S41: =H38+H40 | W41: (+)
B43: Total Kebutuhan Kredit | S43: =S35+S41

Sheet Komite Kredit
A1: KEPUTUSAN KREDIT
A2: No. /Luwuk-KK/XI/2018
R3: Tanggal | U3: =TODAY()
A4: A. | B4: DATA DEBITUR
B5: - | C5: Nama Debitur | I5: : | J5: ='Informasi Pokok'!D12
B6: - | C6: Alamat Debitur | I6: : | J6: ='Informasi Pokok'!D16
B7: - | C7: Pekerjaan | I7: : | J7: Wiraswasta
A9: B. | B9: FASILITAS KREDIT
B10: - | C10: ='Usulan Pembiayaan'!B15 | I10: : | J10: ='Usulan Pembiayaan'!N15 | O10: - | P10: Gol Debitur | U10: : | V10: 875
B11: - | C11: ='Usulan Pembiayaan'!#REF! | I11: : | J11: ='Usulan Pembiayaan'!#REF! | O11: - | P11: Sifat kredit | U11: : | V11: 3
B12: - | C12: ='Usulan Pembiayaan'!#REF! | I12: : | J12: ='Usulan Pembiayaan'!#REF! | O12: - | P12: Jenis Penggunaan | U12: : | V12: 10
B13: - | C13: ='Usulan Pembiayaan'!#REF! | I13: : | J13: ='Usulan Pembiayaan'!#REF! | O13: - | P13: Sektor Ekonomi | U13: : | V13: 1007
B14: - | C14: ='Usulan Pembiayaan'!#REF! | I14: : | J14: ='Usulan Pembiayaan'!#REF! | O14: - | P14: Hub. dengan Bank | U14: : | V14: 02
B15: - | C15: ='Usulan Pembiayaan'!#REF! | I15: : | J15: ='Usulan Pembiayaan'!#REF!
A17: C. | B17: JAMINAN
B18: No | C18: Jenis Agunan | K18: Pengikatan | N18: Nilai Pasar | R18: % | S18: Nilai | W18: Nilai HT
B19: 1 | C19: Tanah pekarangan yang di atasnya berdiri bangunan permanen yang dengan SHM 1698 / Simpong an. Lampani dengan luas 233 bangunan luas 200 m | K19: ='Aspek Non Keuangan'!#REF! | N19: ='Aspek Non Keuangan'!#REF! | R19: 0.8 | S19: ='Aspek Non Keuangan'!#REF! | W19: ='Aspek Non Keuangan'!#REF!
B20: 2 | C20: BPKB Mobil deng No E.9296445 S Merek toyota avanza Warna hitam metalik tahun 2007 dengan no polisi DN 418 cc an. Danny wibowo (telah dibeli debitur terlampir kwitansi pembelian ) | K20: ='Aspek Non Keuangan'!#REF! | N20: ='Aspek Non Keuangan'!#REF! | R20: 0.6 | S20: ='Aspek Non Keuangan'!#REF! | W20: ='Aspek Non Keuangan'!#REF!
B21: 3 | C21: BPKB Mobil deng No K-06931274 Merek Honda city Warna abu -abu hitam metalik tahun 2007 dengan no polisi DN 123 CY an. Sherly lianto (telah dibeli debitur terlampir kwitansi pembelian ) | K21: ='Aspek Non Keuangan'!#REF! | N21: ='Aspek Non Keuangan'!#REF! | R21: 0.6 | S21: ='Aspek Non Keuangan'!#REF! | W21: ='Aspek Non Keuangan'!#REF!
B22: Total | N22: =SUM(N19:Q21) | S22: =SUM(S19:V21) | W22: =SUM(W19:Z21)
B23: Keterangan :
B24: Agunan Kendaraan BPKB No. K-06931274 saling mengikat dengan fasilitas KUB dengan No. Rek Fasilitas 101-001-3693 dengan Plafond Rp. 180.000.000 dan baki debet per tanggal 5 november 2018 sebesar Rp 112.500.000.
A27: D. | B27: PENGIKATAN
B28: - | C28: Pengikatan Kredit diikat Secara | L28: : | M28: Notaril
B29: - | C29: Daftar Asuransi Jiwa | L29: : | M29: Didaftarkan
B30: - | C30: Agunan Kendaraan | L30: : | M30: Diasuransikan (minimal TLO)
A32: Demikian, Keputusan Komite Kredit ini dibuat sebagai pedoman keputusan pemberian kredit.
A34: Pemutus Kredit Non Limit
A35: Area Manager
A39: Akmal Syam | AC39: 3241250
A40: Pemutus Kredit Non Limit | AC40: 874500
A41: Direktur Operasional | AC41: =+AC39-AC40
AC42: 955556 | AD42: =+AC41/AC42
AC43: =+AC41-AC42
A45: Andarias Sam G. Danga
A46: Pemutus Kredit Pemegang Limit
A47: Direktur Utama
A51: Noldi Walelang

Sheet Keputusan Pembiayaan
A2: MEMO KEPUTUSAN PEMBIAYAAN
A6: PERMOHONAN YANG DIAJUKAN
A8: 1 | B8: No. MUP | L8: : | N8: ='Informasi Pokok'!D5
A9: 2 | B9: Kantor | L9: : | N9: ='Informasi Pokok'!D3
A10: 3 | B10: Nama Account Officer | L10: : | N10: ='Informasi Pokok'!D6
A11: 4 | B11: Nama Pemohon | L11: : | N11: ='Informasi Pokok'!D12
A12: 5 | B12: Akad Pembiayaan | L12: : | N12: ='Informasi Pokok'!D67
A13: 6 | B13: Jenis Penggunaan | L13: : | N13: ='Informasi Pokok'!D69
A14: 7 | B14: Besar Permohonan | L14: : | N14: ='Informasi Pokok'!D64
A15: 8 | B15: Jangka Waktu | L15: : | N15: ='Usulan Pembiayaan'!N19&" Bulan"
A16: 9 | B16: Expected Return/Bulan | L16: : | N16: ='Usulan Pembiayaan'!N18 | R16: ='Usulan Pembiayaan'!M82
A17: 10 | B17: Agsuran Perbulan | L17: : | N17: ='Usulan Pembiayaan'!N20
A19: HASIL SCORING DEBITUR
A20: A | B20: INFORMASI DASAR
B21: a. Jenis Kategori Nasabah | M21: ='Informasi Pokok'!D11
B22: b. Jenis Kelamin | M22: ='Informasi Pokok'!D13
B23: c. Usia | M23: ='Informasi Pokok'!I15
B24: d. Status Perkawinan | M24: ='Informasi Pokok'!D22
B25: e. Jumlah Tanggungan | M25: ='Informasi Pokok'!D23 -> 1 - 2 Orang
B26: f. Tingkat Pendidikan | M26: ='Informasi Pokok'!D24
A27: B | B27: TEMPAT TINGGAL NASABAH
B28: a. Kepemilikan Tempat Tinggal | M28: ='Informasi Pokok'!D36
B29: b. Lama Menetap | M29: ='Informasi Pokok'!D37
B30: c. Reputasi di Lingkungan Tempat Tinggal | M30: ='Informasi Pokok'!D38
A31: C | B31: INFORMASI USAHA
B32: a. Jenis Laporan Keuangan | M32: ='Informasi Pokok'!D43
B33: b. Lama Berusaha di Bidang yang Sama | M33: ='Informasi Pokok'!D44
B34: c. Sektor Ekonomi | M34: ='Informasi Pokok'!D68
B35: d. Tujuan Penggunaan Dana | M35: ='Informasi Pokok'!D70
B36: e. Cara Transaksi Usaha | M36: ='Informasi Pokok'!D45
B37: f. Kepemilikan Tempat Usaha | M37: ='Informasi Pokok'!D47
B38: g. Lokasi Usaha | M38: ='Informasi Pokok'!D48
B39: h. Daerah Pemasaran | M39: ='Informasi Pokok'!D49
B40: i. Jumlah Tenaga Kerja | M40: ='Informasi Pokok'!D50
B41: j. Pengelolaan Keuangan Usaha | M41: ='Informasi Pokok'!D51
B42: k. Kewajiban/Utang kepada Pihak Lain | M42: ='Informasi Pokok'!D52
A43: D | B43: HUBUNGAN DENGAN BANK
B44: a. Hubungan Dengan Perbankan | M44: ='Informasi Pokok'!D56
B45: b. Saldo Rekening Rata-rata per Bulan | M45: ='Aspek Keuangan'!W10
B46: c. Mutasi Rekening Rata-rata per Bulan | M46: ='Aspek Keuangan'!W8
...

Sheet Jadang
A1: ="JADWAL ANGSURAN AKAD "&'Keputusan Pembiayaan'!K65&" ("&Q16&")" | H1: ="JADWAL ANGSURAN AKAD "&'Keputusan Pembiayaan'!K65&" ("&R16&")"
A2: ="Atas Nama "&'Keputusan Pembiayaan'!N11 | H2: =A2 | P2: ='Usulan Pembiayaan'!J80
B3: 1 | C3: ='Informasi Pokok'!D7 | I3: 1
C4: OS. Pokok | D4: Pokok | E4: Margin | J4: OS. Pokok | K4: Pokok | L4: Margin | P4: Flat | Q4: jw | S4: ='Usulan Pembiayaan'!J81
A5: No. | B5: Tanggal | F5: Total Angsuran | H5: No. | I5: Tanggal | M5: Total Angsuran | P5: Efektif | Q5: flat | S5: =P28 | U5: Flat | Y5: Efektif
Q6: efektif | S6: =R28 | T6: =RATE(S4,X8,-P2)*12 | U6: os pokok | V6: Pokok | W6: Margin | X6: tot angsur | Y6: os pokok | Z6: Pokok | AA6: margin | AB6: total
Y7: o
A8: 1 | B8: =IF(C3="","",DATE(YEAR(C3),MONTH(C3)+$B$3,DAY(C3))) | C8: =IF($Q$16="Flat",U8,Y8) | D8: =IF($Q$16="Flat",V8,Z8) | E8: =IF($Q$16="Flat",W8,AA8) | F8: =D8+E8 | H8: 1 | I8: =B8 | J8: =IF($Q$16="Flat",Y8,U8) | K8: =IF($Q$16="Flat",Z8,V8) | L8: =IF($Q$16="Flat",AA8,W8) | M8: =K8+L8 | U8: =P2 | V8: =Q17/Q18 | W8: =Q17*P28 | X8: =V8+W8 | Y8: =P2 | Z8: =AB8-AA8 | AA8: =(ROUNDDOWN(Y8*$S$6/12,1)) | AB8: =PMT(S6/12,S4,-P2)
A9: 2 | B9: =IF(B8="","",DATE(YEAR(B8),MONTH(B8)+$B$3,DAY(B8))) | C9: =IF($Q$16="Flat",U9,Y9) | D9: =IF($Q$16="Flat",V9,Z9) | E9: =IF($Q$16="Flat",W9,AA9) | F9: =D9+E9 | H9: 2 | I9: =IF(I8="","",DATE(YEAR(I8),MONTH(I8)+$B$3,DAY(I8))) | J9: =IF($Q$16="Flat",Y9,U9) | K9: =IF($Q$16="Flat",Z9,V9) | L9: =IF($Q$16="Flat",AA9,W9) | M9: =K9+L9 | U9: =U8-V8 | V9: =IF(A9<=$S$4,V8,0) | W9: =IF(A9<=$S$4,W8,0) | X9: =V9+W9 | Y9: =IF(A9<=$S$4,Y8-Z8,0) | Z9: =AB9-AA9 | AA9: =IF(A9<=$S$4,Y9*$S$6/12,0) | AB9: =IF(A9<=$S$4,$AB$8,0)
A10: 3 | B10: =IF(B9="","",DATE(YEAR(B9),MONTH(B9)+$B$3,DAY(B9))) | C10: =IF($Q$16="Flat",U10,Y10) | D10: =IF($Q$16="Flat",V10,Z10) | E10: =IF($Q$16="Flat",W10,AA10) | F10: =D10+E10 | H10: 3 | I10: =IF(I9="","",DATE(YEAR(I9),MONTH(I9)+$B$3,DAY(I9))) | J10: =IF($Q$16="Flat",Y10,U10) | K10: =IF($Q$16="Flat",Z10,V10) | L10: =IF($Q$16="Flat",AA10,W10) | M10: =K10+L10 | U10: =U9-V9 | V10: =IF(A10<=$S$4,V9,0) | W10: =IF(A10<=$S$4,W9,0) | X10: =V10+W10 | Y10: =IF(A10<=$S$4,Y9-Z9,0) | Z10: =AB10-AA10 | AA10: =IF(A10<=$S$4,Y10*$S$6/12,0) | AB10: =IF(A10<=$S$4,$AB$8,0)
A11: 4 | B11: =IF(B10="","",DATE(YEAR(B10),MONTH(B10)+$B$3,DAY(B10))) | C11: =IF($Q$16="Flat",U11,Y11) | D11: =IF($Q$16="Flat",V11,Z11) | E11: =IF($Q$16="Flat",W11,AA11) | F11: =D11+E11 | H11: 4 | I11: =IF(I10="","",DATE(YEAR(I10),MONTH(I10)+$B$3,DAY(I10))) | J11: =IF($Q$16="Flat",Y11,U11) | K11: =IF($Q$16="Flat",Z11,V11) | L11: =IF($Q$16="Flat",AA11,W11) | M11: =K11+L11 | U11: =U10-V10 | V11: =IF(A11<=$S$4,V10,0) | W11: =IF(A11<=$S$4,W10,0) | X11: =V11+W11 | Y11: =IF(A11<=$S$4,Y10-Z10,0) | Z11: =AB11-AA11 | AA11: =IF(A11<=$S$4,Y11*$S$6/12,0) | AB11: =IF(A11<=$S$4,$AB$8,0)
A12: 5 | B12: =IF(B11="","",DATE(YEAR(B11),MONTH(B11)+$B$3,DAY(B11))) | C12: =IF($Q$16="Flat",U12,Y12) | D12: =IF($Q$16="Flat",V12,Z12) | E12: =IF($Q$16="Flat",W12,AA12) | F12: =D12+E12 | H12: 5 | I12: =IF(I11="","",DATE(YEAR(I11),MONTH(I11)+$B$3,DAY(I11))) | J12: =IF($Q$16="Flat",Y12,U12) | K12: =IF($Q$16="Flat",Z12,V12) | L12: =IF($Q$16="Flat",AA12,W12) | M12: =K12+L12 | U12: =U11-V11 | V12: =IF(A12<=$S$4,V11,0) | W12: =IF(A12<=$S$4,W11,0) | X12: =V12+W12 | Y12: =IF(A12<=$S$4,Y11-Z11,0) | Z12: =AB12-AA12 | AA12: =IF(A12<=$S$4,Y12*$S$6/12,0) | AB12: =IF(A12<=$S$4,$AB$8,0)
A13: 6 | B13: =IF(B12="","",DATE(YEAR(B12),MONTH(B12)+$B$3,DAY(B12))) | C13: =IF($Q$16="Flat",U13,Y13) | D13: =IF($Q$16="Flat",V13,Z13) | E13: =IF($Q$16="Flat",W13,AA13) | F13: =D13+E13 | H13: 6 | I13: =IF(I12="","",DATE(YEAR(I12),MONTH(I12)+$B$3,DAY(I12))) | J13: =IF($Q$16="Flat",Y13,U13) | K13: =IF($Q$16="Flat",Z13,V13) | L13: =IF($Q$16="Flat",AA13,W13) | M13: =K13+L13 | U13: =U12-V12 | V13: =IF(A13<=$S$4,V12,0) | W13: =IF(A13<=$S$4,W12,0) | X13: =V13+W13 | Y13: =IF(A13<=$S$4,Y12-Z12,0) | Z13: =AB13-AA13 | AA13: =IF(A13<=$S$4,Y13*$S$6/12,0) | AB13: =IF(A13<=$S$4,$AB$8,0)
A14: 7 | B14: =IF(B13="","",DATE(YEAR(B13),MONTH(B13)+$B$3,DAY(B13))) | C14: =IF($Q$16="Flat",U14,Y14) | D14: =IF($Q$16="Flat",V14,Z14) | E14: =IF($Q$16="Flat",W14,AA14) | F14: =D14+E14 | H14: 7 | I14: =IF(I13="","",DATE(YEAR(I13),MONTH(I13)+$B$3,DAY(I13))) | J14: =IF($Q$16="Flat",Y14,U14) | K14: =IF($Q$16="Flat",Z14,V14) | L14: =IF($Q$16="Flat",AA14,W14) | M14: =K14+L14 | U14: =U13-V13 | V14: =IF(A14<=$S$4,V13,0) | W14: =IF(A14<=$S$4,W13,0) | X14: =V14+W14 | Y14: =IF(A14<=$S$4,Y13-Z13,0) | Z14: =AB14-AA14 | AA14: =IF(A14<=$S$4,Y14*$S$6/12,0) | AB14: =IF(A14<=$S$4,$AB$8,0)
A15: 8 | B15: =IF(B14="","",DATE(YEAR(B14),MONTH(B14)+$B$3,DAY(B14))) | C15: =IF($Q$16="Flat",U15,Y15) | D15: =IF($Q$16="Flat",V15,Z15) | E15: =IF($Q$16="Flat",W15,AA15) | F15: =D15+E15 | H15: 8 | I15: =IF(I14="","",DATE(YEAR(I14),MONTH(I14)+$B$3,DAY(I14))) | J15: =IF($Q$16="Flat",Y15,U15) | K15: =IF($Q$16="Flat",Z15,V15) | L15: =IF($Q$16="Flat",AA15,W15) | M15: =K15+L15 | P15: DATA | U15: =U14-V14 | V15: =IF(A15<=$S$4,V14,0) | W15: =IF(A15<=$S$4,W14,0) | X15: =V15+W15 | Y15: =IF(A15<=$S$4,Y14-Z14,0) | Z15: =AB15-AA15 | AA15: =IF(A15<=$S$4,Y15*$S$6/12,0) | AB15: =IF(A15<=$S$4,$AB$8,0)
A16: 9 | B16: =IF(B15="","",DATE(YEAR(B15),MONTH(B15)+$B$3,DAY(B15))) | C16: =IF($Q$16="Flat",U16,Y16) | D16: =IF($Q$16="Flat",V16,Z16) | E16: =IF($Q$16="Flat",W16,AA16) | F16: =D16+E16 | H16: 9 | I16: =IF(I15="","",DATE(YEAR(I15),MONTH(I15)+$B$3,DAY(I15))) | J16: =IF($Q$16="Flat",Y16,U16) | K16: =IF($Q$16="Flat",Z16,V16) | L16: =IF($Q$16="Flat",AA16,W16) | M16: =K16+L16 | P16: Jenis Margin | Q16: ='Usulan Pembiayaan'!M82 | R16: =IF(Q16="Flat",P5,P4) | U16: =U15-V15 | V16: =IF(A16<=$S$4,V15,0) | W16: =IF(A16<=$S$4,W15,0) | X16: =V16+W16 | Y16: =IF(A16<=$S$4,Y15-Z15,0) | Z16: =AB16-AA16 | AA16: =IF(A16<=$S$4,Y16*$S$6/12,0) | AB16: =IF(A16<=$S$4,$AB$8,0)
A17: 10 | B17: =IF(B16="","",DATE(YEAR(B16),MONTH(B16)+$B$3,DAY(B16))) | C17: =IF($Q$16="Flat",U17,Y17) | D17: =IF($Q$16="Flat",V17,Z17) | E17: =IF($Q$16="Flat",W17,AA17) | F17: =D17+E17 | H17: 10 | I17: =IF(I16="","",DATE(YEAR(I16),MONTH(I16)+$B$3,DAY(I16))) | J17: =IF($Q$16="Flat",Y17,U17) | K17: =IF($Q$16="Flat",Z17,V17) | L17: =IF($Q$16="Flat",AA17,W17) | M17: =K17+L17 | P17: Plafond | Q17: ='Usulan Pembiayaan'!J80 | U17: =U16-V16 | V17: =IF(A17<=$S$4,V16,0) | W17: =IF(A17<=$S$4,W16,0) | X17: =V17+W17 | Y17: =IF(A17<=$S$4,Y16-Z16,0) | Z17: =AB17-AA17 | AA17: =IF(A17<=$S$4,Y17*$S$6/12,0) | AB17: =IF(A17<=$S$4,$AB$8,0)
A18: 11 | B18: =IF(B17="","",DATE(YEAR(B17),MONTH(B17)+$B$3,DAY(B17))) | C18: =IF($Q$16="Flat",U18,Y18) | D18: =IF($Q$16="Flat",V18,Z18) | E18: =IF($Q$16="Flat",W18,AA18) | F18: =D18+E18 | H18: 11 | I18: =IF(I17="","",DATE(YEAR(I17),MONTH(I17)+$B$3,DAY(I17))) | J18: =IF($Q$16="Flat",Y18,U18) | K18: =IF($Q$16="Flat",Z18,V18) | L18: =IF($Q$16="Flat",AA18,W18) | M18: =K18+L18 | P18: Jangka Waktu | Q18: ='Usulan Pembiayaan'!J81 | U18: =U17-V17 | V18: =IF(A18<=$S$4,V17,0) | W18: =IF(A18<=$S$4,W17,0) | X18: =V18+W18 | Y18: =IF(A18<=$S$4,Y17-Z17,0) | Z18: =AB18-AA18 | AA18: =IF(A18<=$S$4,Y18*$S$6/12,0) | AB18: =IF(A18<=$S$4,$AB$8,0)
A19: 12 | B19: =IF(B18="","",DATE(YEAR(B18),MONTH(B18)+$B$3,DAY(B18))) | C19: =IF($Q$16="Flat",U19,Y19) | D19: =IF($Q$16="Flat",V19,Z19) | E19: =IF($Q$16="Flat",W19,AA19) | F19: =D19+E19 | H19: 12 | I19: =IF(I18="","",DATE(YEAR(I18),MONTH(I18)+$B$3,DAY(I18))) | J19: =IF($Q$16="Flat",Y19,U19) | K19: =IF($Q$16="Flat",Z19,V19) | L19: =IF($Q$16="Flat",AA19,W19) | M19: =K19+L19 | P19: %Margin/bulan | Q19: ='Usulan Pembiayaan'!J82 | U19: =U18-V18 | V19: =IF(A19<=$S$4,V18,0) | W19: =IF(A19<=$S$4,W18,0) | X19: =V19+W19 | Y19: =IF(A19<=$S$4,Y18-Z18,0) | Z19: =AB19-AA19 | AA19: =IF(A19<=$S$4,Y19*$S$6/12,0) | AB19: =IF(A19<=$S$4,$AB$8,0)
A20: 13 | B20: =IF(B19="","",DATE(YEAR(B19),MONTH(B19)+$B$3,DAY(B19))) | C20: =IF($Q$16="Flat",U20,Y20) | D20: =IF($Q$16="Flat",V20,Z20) | E20: =IF($Q$16="Flat",W20,AA20) | F20: =D20+E20 | H20: 13 | I20: =IF(I19="","",DATE(YEAR(I19),MONTH(I19)+$B$3,DAY(I19))) | J20: =IF($Q$16="Flat",Y20,U20) | K20: =IF($Q$16="Flat",Z20,V20) | L20: =IF($Q$16="Flat",AA20,W20) | M20: =K20+L20 | P20: Angsuran | Q20: =IF(Q16="Flat",((Q17/Q18)+(Q17*Q19)),PMT(Q19,Q18,-Q17)) | U20: =U19-V19 | V20: =IF(A20<=$S$4,V19,0) | W20: =IF(A20<=$S$4,W19,0) | X20: =V20+W20 | Y20: =IF(A20<=$S$4,Y19-Z19,0) | Z20: =AB20-AA20 | AA20: =IF(A20<=$S$4,Y20*$S$6/12,0) | AB20: =IF(A20<=$S$4,$AB$8,0)
A21: 14 | B21: =IF(B20="","",DATE(YEAR(B20),MONTH(B20)+$B$3,DAY(B20))) | C21: =IF($Q$16="Flat",U21,Y21) | D21: =IF($Q$16="Flat",V21,Z21) | E21: =IF($Q$16="Flat",W21,AA21) | F21: =D21+E21 | H21: 14 | I21: =IF(I20="","",DATE(YEAR(I20),MONTH(I20)+$B$3,DAY(I20))) | J21: =IF($Q$16="Flat",Y21,U21) | K21: =IF($Q$16="Flat",Z21,V21) | L21: =IF($Q$16="Flat",AA21,W21) | M21: =K21+L21 | U21: =U20-V20 | V21: =IF(A21<=$S$4,V20,0) | W21: =IF(A21<=$S$4,W20,0) | X21: =V21+W21 | Y21: =IF(A21<=$S$4,Y20-Z20,0) | Z21: =AB21-AA21 | AA21: =IF(A21<=$S$4,Y21*$S$6/12,0) | AB21: =IF(A21<=$S$4,$AB$8,0)
A22: 15 | B22: =IF(B21="","",DATE(YEAR(B21),MONTH(B21)+$B$3,DAY(B21))) | C22: =IF($Q$16="Flat",U22,Y22) | D22: =IF($Q$16="Flat",V22,Z22) | E22: =IF($Q$16="Flat",W22,AA22) | F22: =D22+E22 | H22: 15 | I22: =IF(I21="","",DATE(YEAR(I21),MONTH(I21)+$B$3,DAY(I21))) | J22: =IF($Q$16="Flat",Y22,U22) | K22: =IF($Q$16="Flat",Z22,V22) | L22: =IF($Q$16="Flat",AA22,W22) | M22: =K22+L22 | P22: KONVERSI | U22: =U21-V21 | V22: =IF(A22<=$S$4,V21,0) | W22: =IF(A22<=$S$4,W21,0) | X22: =V22+W22 | Y22: =IF(A22<=$S$4,Y21-Z21,0) | Z22: =AB22-AA22 | AA22: =IF(A22<=$S$4,Y22*$S$6/12,0) | AB22: =IF(A22<=$S$4,$AB$8,0)
A23: 16 | B23: =IF(B22="","",DATE(YEAR(B22),MONTH(B22)+$B$3,DAY(B22))) | C23: =IF($Q$16="Flat",U23,Y23) | D23: =IF($Q$16="Flat",V23,Z23) | E23: =IF($Q$16="Flat",W23,AA23) | F23: =D23+E23 | H23: 16 | I23: =IF(I22="","",DATE(YEAR(I22),MONTH(I22)+$B$3,DAY(I22))) | J23: =IF($Q$16="Flat",Y23,U23) | K23: =IF($Q$16="Flat",Z23,V23) | L23: =IF($Q$16="Flat",AA23,W23) | M23: =K23+L23 | P23: Jenis Margin | Q23: =IF(Q16="Flat","Efektif","Flat") | U23: =U22-V22 | V23: =IF(A23<=$S$4,V22,0) | W23: =IF(A23<=$S$4,W22,0) | X23: =V23+W23 | Y23: =IF(A23<=$S$4,Y22-Z22,0) | Z23: =AB23-AA23 | AA23: =IF(A23<=$S$4,Y23*$S$6/12,0) | AB23: =IF(A23<=$S$4,$AB$8,0)
A24: 17 | B24: =IF(B23="","",DATE(YEAR(B23),MONTH(B23)+$B$3,DAY(B23))) | C24: =IF($Q$16="Flat",U24,Y24) | D24: =IF($Q$16="Flat",V24,Z24) | E24: =IF($Q$16="Flat",W24,AA24) | F24: =D24+E24 | H24: 17 | I24: =IF(I23="","",DATE(YEAR(I23),MONTH(I23)+$B$3,DAY(I23))) | J24: =IF($Q$16="Flat",Y24,U24) | K24: =IF($Q$16="Flat",Z24,V24) | L24: =IF($Q$16="Flat",AA24,W24) | M24: =K24+L24 | P24: %Margin/bulan | Q24: =IF(Q23="Flat",((Q20/Q17)-(1/Q18)),RATE(Q18,Q20,-Q17)) | U24: =U23-V23 | V24: =IF(A24<=$S$4,V23,0) | W24: =IF(A24<=$S$4,W23,0) | X24: =V24+W24 | Y24: =IF(A24<=$S$4,Y23-Z23,0) | Z24: =AB24-AA24 | AA24: =IF(A24<=$S$4,Y24*$S$6/12,0) | AB24: =IF(A24<=$S$4,$AB$8,0)
A25: 18 | B25: =IF(B24="","",DATE(YEAR(B24),MONTH(B24)+$B$3,DAY(B24))) | C25: =IF($Q$16="Flat",U25,Y25) | D25: =IF($Q$16="Flat",V25,Z25) | E25: =IF($Q$16="Flat",W25,AA25) | F25: =D25+E25 | H25: 18 | I25: =IF(I24="","",DATE(YEAR(I24),MONTH(I24)+$B$3,DAY(I24))) | J25: =IF($Q$16="Flat",Y25,U25) | K25: =IF($Q$16="Flat",Z25,V25) | L25: =IF($Q$16="Flat",AA25,W25) | M25: =K25+L25 | P25: Angsuran | Q25: =IF(Q23="Flat",((Q17/Q18)+(Q17*Q24)),IF(Q23="Efektif",PMT(Q24,Q18,-Q17))) | U25: =U24-V24 | V25: =IF(A25<=$S$4,V24,0) | W25: =IF(A25<=$S$4,W24,0) | X25: =V25+W25 | Y25: =IF(A25<=$S$4,Y24-Z24,0) | Z25: =AB25-AA25 | AA25: =IF(A25<=$S$4,Y25*$S$6/12,0) | AB25: =IF(A25<=$S$4,$AB$8,0)
A26: 19 | B26: =IF(B25="","",DATE(YEAR(B25),MONTH(B25)+$B$3,DAY(B25))) | C26: =IF($Q$16="Flat",U26,Y26) | D26: =IF($Q$16="Flat",V26,Z26) | E26: =IF($Q$16="Flat",W26,AA26) | F26: =D26+E26 | H26: 19 | I26: =IF(I25="","",DATE(YEAR(I25),MONTH(I25)+$B$3,DAY(I25))) | J26: =IF($Q$16="Flat",Y26,U26) | K26: =IF($Q$16="Flat",Z26,V26) | L26: =IF($Q$16="Flat",AA26,W26) | M26: =K26+L26 | U26: =U25-V25 | V26: =IF(A26<=$S$4,V25,0) | W26: =IF(A26<=$S$4,W25,0) | X26: =V26+W26 | Y26: =IF(A26<=$S$4,Y25-Z25,0) | Z26: =AB26-AA26 | AA26: =IF(A26<=$S$4,Y26*$S$6/12,0) | AB26: =IF(A26<=$S$4,$AB$8,0)
A27: 20 | B27: =IF(B26="","",DATE(YEAR(B26),MONTH(B26)+$B$3,DAY(B26))) | C27: =IF($Q$16="Flat",U27,Y27) | D27: =IF($Q$16="Flat",V27,Z27) | E27: =IF($Q$16="Flat",W27,AA27) | F27: =D27+E27 | H27: 20 | I27: =IF(I26="","",DATE(YEAR(I26),MONTH(I26)+$B$3,DAY(I26))) | J27: =IF($Q$16="Flat",Y27,U27) | K27: =IF($Q$16="Flat",Z27,V27) | L27: =IF($Q$16="Flat",AA27,W27) | M27: =K27+L27 | P27: FLAT | Q27: EFEKTIF | U27: =U26-V26 | V27: =IF(A27<=$S$4,V26,0) | W27: =IF(A27<=$S$4,W26,0) | X27: =V27+W27 | Y27: =IF(A27<=$S$4,Y26-Z26,0) | Z27: =AB27-AA27 | AA27: =IF(A27<=$S$4,Y27*$S$6/12,0) | AB27: =IF(A27<=$S$4,$AB$8,0)
A28: 21 | B28: =IF(B27="","",DATE(YEAR(B27),MONTH(B27)+$B$3,DAY(B27))) | C28: =IF($Q$16="Flat",U28,Y28) | D28: =IF($Q$16="Flat",V28,Z28) | E28: =IF($Q$16="Flat",W28,AA28) | F28: =D28+E28 | H28: 21 | I28: =IF(I27="","",DATE(YEAR(I27),MONTH(I27)+$B$3,DAY(I27))) | J28: =IF($Q$16="Flat",Y28,U28) | K28: =IF($Q$16="Flat",Z28,V28) | L28: =IF($Q$16="Flat",AA28,W28) | M28: =K28+L28 | O28: =P28*12 | P28: =IF(Q23="Flat",Q24,IF(Q23="Efektif",Q19)) | Q28: =IF(Q23="Efektif",Q24,IF(Q23="Flat",Q19)) | R28: =Q28*12 | U28: =U27-V27 | V28: =IF(A28<=$S$4,V27,0) | W28: =IF(A28<=$S$4,W27,0) | X28: =V28+W28 | Y28: =IF(A28<=$S$4,Y27-Z27,0) | Z28: =AB28-AA28 | AA28: =IF(A28<=$S$4,Y28*$S$6/12,0) | AB28: =IF(A28<=$S$4,$AB$8,0)
A29: 22 | B29: =IF(B28="","",DATE(YEAR(B28),MONTH(B28)+$B$3,DAY(B28))) | C29: =IF($Q$16="Flat",U29,Y29) | D29: =IF($Q$16="Flat",V29,Z29) | E29: =IF($Q$16="Flat",W29,AA29) | F29: =D29+E29 | H29: 22 | I29: =IF(I28="","",DATE(YEAR(I28),MONTH(I28)+$B$3,DAY(I28))) | J29: =IF($Q$16="Flat",Y29,U29) | K29: =IF($Q$16="Flat",Z29,V29) | L29: =IF($Q$16="Flat",AA29,W29) | M29: =K29+L29 | U29: =U28-V28 | V29: =IF(A29<=$S$4,V28,0) | W29: =IF(A29<=$S$4,W28,0) | X29: =V29+W29 | Y29: =IF(A29<=$S$4,Y28-Z28,0) | Z29: =AB29-AA29 | AA29: =IF(A29<=$S$4,Y29*$S$6/12,0) | AB29: =IF(A29<=$S$4,$AB$8,0)
A30: 23 | B30: =IF(B29="","",DATE(YEAR(B29),MONTH(B29)+$B$3,DAY(B29))) | C30: =IF($Q$16="Flat",U30,Y30) | D30: =IF($Q$16="Flat",V30,Z30) | E30: =IF($Q$16="Flat",W30,AA30) | F30: =D30+E30 | H30: 23 | I30: =IF(I29="","",DATE(YEAR(I29),MONTH(I29)+$B$3,DAY(I29))) | J30: =IF($Q$16="Flat",Y30,U30) | K30: =IF($Q$16="Flat",Z30,V30) | L30: =IF($Q$16="Flat",AA30,W30) | M30: =K30+L30 | U30: =U29-V29 | V30: =IF(A30<=$S$4,V29,0) | W30: =IF(A30<=$S$4,W29,0) | X30: =V30+W30 | Y30: =IF(A30<=$S$4,Y29-Z29,0) | Z30: =AB30-AA30 | AA30: =IF(A30<=$S$4,Y30*$S$6/12,0) | AB30: =IF(A30<=$S$4,$AB$8,0)
A31: 24 | B31: =IF(B30="","",DATE(YEAR(B30),MONTH(B30)+$B$3,DAY(B30))) | C31: =IF($Q$16="Flat",U31,Y31) | D31: =IF($Q$16="Flat",V31,Z31) | E31: =IF($Q$16="Flat",W31,AA31) | F31: =D31+E31 | H31: 24 | I31: =IF(I30="","",DATE(YEAR(I30),MONTH(I30)+$B$3,DAY(I30))) | J31: =IF($Q$16="Flat",Y31,U31) | K31: =IF($Q$16="Flat",Z31,V31) | L31: =IF($Q$16="Flat",AA31,W31) | M31: =K31+L31 | U31: =U30-V30 | V31: =IF(A31<=$S$4,V30,0) | W31: =IF(A31<=$S$4,W30,0) | X31: =V31+W31 | Y31: =IF(A31<=$S$4,Y30-Z30,0) | Z31: =AB31-AA31 | AA31: =IF(A31<=$S$4,Y31*$S$6/12,0) | AB31: =IF(A31<=$S$4,$AB$8,0)
A32: 25 | B32: =IF(B31="","",DATE(YEAR(B31),MONTH(B31)+$B$3,DAY(B31))) | C32: =IF($Q$16="Flat",U32,Y32) | D32: =IF($Q$16="Flat",V32,Z32) | E32: =IF($Q$16="Flat",W32,AA32) | F32: =D32+E32 | H32: 25 | I32: =IF(I31="","",DATE(YEAR(I31),MONTH(I31)+$B$3,DAY(I31))) | J32: =IF($Q$16="Flat",Y32,U32) | K32: =IF($Q$16="Flat",Z32,V32) | L32: =IF($Q$16="Flat",AA32,W32) | M32: =K32+L32 | U32: =U31-V31 | V32: =IF(A32<=$S$4,V31,0) | W32: =IF(A32<=$S$4,W31,0) | X32: =V32+W32 | Y32: =IF(A32<=$S$4,Y31-Z31,0) | Z32: =AB32-AA32 | AA32: =IF(A32<=$S$4,Y32*$S$6/12,0) | AB32: =IF(A32<=$S$4,$AB$8,0)
A33: 26 | B33: =IF(B32="","",DATE(YEAR(B32),MONTH(B32)+$B$3,DAY(B32))) | C33: =IF($Q$16="Flat",U33,Y33) | D33: =IF($Q$16="Flat",V33,Z33) | E33: =IF($Q$16="Flat",W33,AA33) | F33: =D33+E33 | H33: 26 | I33: =IF(I32="","",DATE(YEAR(I32),MONTH(I32)+$B$3,DAY(I32))) | J33: =IF($Q$16="Flat",Y33,U33) | K33: =IF($Q$16="Flat",Z33,V33) | L33: =IF($Q$16="Flat",AA33,W33) | M33: =K33+L33 | U33: =U32-V32 | V33: =IF(A33<=$S$4,V32,0) | W33: =IF(A33<=$S$4,W32,0) | X33: =V33+W33 | Y33: =IF(A33<=$S$4,Y32-Z32,0) | Z33: =AB33-AA33 | AA33: =IF(A33<=$S$4,Y33*$S$6/12,0) | AB33: =IF(A33<=$S$4,$AB$8,0)
A34: 27 | B34: =IF(B33="","",DATE(YEAR(B33),MONTH(B33)+$B$3,DAY(B33))) | C34: =IF($Q$16="Flat",U34,Y34) | D34: =IF($Q$16="Flat",V34,Z34) | E34: =IF($Q$16="Flat",W34,AA34) | F34: =D34+E34 | H34: 27 | I34: =IF(I33="","",DATE(YEAR(I33),MONTH(I33)+$B$3,DAY(I33))) | J34: =IF($Q$16="Flat",Y34,U34) | K34: =IF($Q$16="Flat",Z34,V34) | L34: =IF($Q$16="Flat",AA34,W34) | M34: =K34+L34 | U34: =U33-V33 | V34: =IF(A34<=$S$4,V33,0) | W34: =IF(A34<=$S$4,W33,0) | X34: =V34+W34 | Y34: =IF(A34<=$S$4,Y33-Z33,0) | Z34: =AB34-AA34 | AA34: =IF(A34<=$S$4,Y34*$S$6/12,0) | AB34: =IF(A34<=$S$4,$AB$8,0)
A35: 28 | B35: =IF(B34="","",DATE(YEAR(B34),MONTH(B34)+$B$3,DAY(B34))) | C35: =IF($Q$16="Flat",U35,Y35) | D35: =IF($Q$16="Flat",V35,Z35) | E35: =IF($Q$16="Flat",W35,AA35) | F35: =D35+E35 | H35: 28 | I35: =IF(I34="","",DATE(YEAR(I34),MONTH(I34)+$B$3,DAY(I34))) | J35: =IF($Q$16="Flat",Y35,U35) | K35: =IF($Q$16="Flat",Z35,V35) | L35: =IF($Q$16="Flat",AA35,W35) | M35: =K35+L35 | U35: =U34-V34 | V35: =IF(A35<=$S$4,V34,0) | W35: =IF(A35<=$S$4,W34,0) | X35: =V35+W35 | Y35: =IF(A35<=$S$4,Y34-Z34,0) | Z35: =AB35-AA35 | AA35: =IF(A35<=$S$4,Y35*$S$6/12,0) | AB35: =IF(A35<=$S$4,$AB$8,0)
A36: 29 | B36: =IF(B35="","",DATE(YEAR(B35),MONTH(B35)+$B$3,DAY(B35))) | C36: =IF($Q$16="Flat",U36,Y36) | D36: =IF($Q$16="Flat",V36,Z36) | E36: =IF($Q$16="Flat",W36,AA36) | F36: =D36+E36 | H36: 29 | I36: =IF(I35="","",DATE(YEAR(I35),MONTH(I35)+$B$3,DAY(I35))) | J36: =IF($Q$16="Flat",Y36,U36) | K36: =IF($Q$16="Flat",Z36,V36) | L36: =IF($Q$16="Flat",AA36,W36) | M36: =K36+L36 | U36: =U35-V35 | V36: =IF(A36<=$S$4,V35,0) | W36: =IF(A36<=$S$4,W35,0) | X36: =V36+W36 | Y36: =IF(A36<=$S$4,Y35-Z35,0) | Z36: =AB36-AA36 | AA36: =IF(A36<=$S$4,Y36*$S$6/12,0) | AB36: =IF(A36<=$S$4,$AB$8,0)
A37: 30 | B37: =IF(B36="","",DATE(YEAR(B36),MONTH(B36)+$B$3,DAY(B36))) | C37: =IF($Q$16="Flat",U37,Y37) | D37: =IF($Q$16="Flat",V37,Z37) | E37: =IF($Q$16="Flat",W37,AA37) | F37: =D37+E37 | H37: 30 | I37: =IF(I36="","",DATE(YEAR(I36),MONTH(I36)+$B$3,DAY(I36))) | J37: =IF($Q$16="Flat",Y37,U37) | K37: =IF($Q$16="Flat",Z37,V37) | L37: =IF($Q$16="Flat",AA37,W37) | M37: =K37+L37 | U37: =U36-V36 | V37: =IF(A37<=$S$4,V36,0) | W37: =IF(A37<=$S$4,W36,0) | X37: =V37+W37 | Y37: =IF(A37<=$S$4,Y36-Z36,0) | Z37: =AB37-AA37 | AA37: =IF(A37<=$S$4,Y37*$S$6/12,0) | AB37: =IF(A37<=$S$4,$AB$8,0)
A38: 31 | B38: =IF(B37="","",DATE(YEAR(B37),MONTH(B37)+$B$3,DAY(B37))) | C38: =IF($Q$16="Flat",U38,Y38) | D38: =IF($Q$16="Flat",V38,Z38) | E38: =IF($Q$16="Flat",W38,AA38) | F38: =D38+E38 | H38: 31 | I38: =IF(I37="","",DATE(YEAR(I37),MONTH(I37)+$B$3,DAY(I37))) | J38: =IF($Q$16="Flat",Y38,U38) | K38: =IF($Q$16="Flat",Z38,V38) | L38: =IF($Q$16="Flat",AA38,W38) | M38: =K38+L38 | U38: =U37-V37 | V38: =IF(A38<=$S$4,V37,0) | W38: =IF(A38<=$S$4,W37,0) | X38: =V38+W38 | Y38: =IF(A38<=$S$4,Y37-Z37,0) | Z38: =AB38-AA38 | AA38: =IF(A38<=$S$4,Y38*$S$6/12,0) | AB38: =IF(A38<=$S$4,$AB$8,0)
A39: 32 | B39: =IF(B38="","",DATE(YEAR(B38),MONTH(B38)+$B$3,DAY(B38))) | C39: =IF($Q$16="Flat",U39,Y39) | D39: =IF($Q$16="Flat",V39,Z39) | E39: =IF($Q$16="Flat",W39,AA39) | F39: =D39+E39 | H39: 32 | I39: =IF(I38="","",DATE(YEAR(I38),MONTH(I38)+$B$3,DAY(I38))) | J39: =IF($Q$16="Flat",Y39,U39) | K39: =IF($Q$16="Flat",Z39,V39) | L39: =IF($Q$16="Flat",AA39,W39) | M39: =K39+L39 | U39: =U38-V38 | V39: =IF(A39<=$S$4,V38,0) | W39: =IF(A39<=$S$4,W38,0) | X39: =V39+W39 | Y39: =IF(A39<=$S$4,Y38-Z38,0) | Z39: =AB39-AA39 | AA39: =IF(A39<=$S$4,Y39*$S$6/12,0) | AB39: =IF(A39<=$S$4,$AB$8,0)
A40: 33 | B40: =IF(B39="","",DATE(YEAR(B39),MONTH(B39)+$B$3,DAY(B39))) | C40: =IF($Q$16="Flat",U40,Y40) | D40: =IF($Q$16="Flat",V40,Z40) | E40: =IF($Q$16="Flat",W40,AA40) | F40: =D40+E40 | H40: 33 | I40: =IF(I39="","",DATE(YEAR(I39),MONTH(I39)+$B$3,DAY(I39))) | J40: =IF($Q$16="Flat",Y40,U40) | K40: =IF($Q$16="Flat",Z40,V40) | L40: =IF($Q$16="Flat",AA40,W40) | M40: =K40+L40 | U40: =U39-V39 | V40: =IF(A40<=$S$4,V39,0) | W40: =IF(A40<=$S$4,W39,0) | X40: =V40+W40 | Y40: =IF(A40<=$S$4,Y39-Z39,0) | Z40: =AB40-AA40 | AA40: =IF(A40<=$S$4,Y40*$S$6/12,0) | AB40: =IF(A40<=$S$4,$AB$8,0)
...

Sheet Parameter
A1: PARAMETER KREDIT SCORING KCR | H1: EXISTING | L1: <=50juta
H2: BBT (a) | I2: % Fktr (b) | J2: % Var © | K2: Nilai = a x b x c | L2: BBT (a) | M2: % Fktr (b) | N2: % Var © | O2: Nilai = a x b x c
A4: STEP 1 - INFORMASI DASAR
A5: (a) | B5: Usia Calon Nasabah | U5: Tering
D6: 1 | E6: 21 - 30 tahun | H6: 50 | I6: 0.1 | J6: 0.2 | K6: =H6*I6*J6 | L6: 50 | M6: 0.05 | N6: 0.3 | O6: =L6*M6*N6
D7: 2 | E7: 31 - 40 tahun | H7: 85 | I7: 0.1 | J7: 0.2 | K7: =H7*I7*J7 | L7: 85 | M7: 0.05 | N7: 0.3 | O7: =L7*M7*N7 | P7: =K8 | Q7: =K7 | R7: =K9 | S7: =K6 | U7: =VLOOKUP('Informasi Pokok'!I15,Parameter!E6:K9,7,0)
D8: 3 | E8: 41 - 55 tahun | H8: 100 | I8: 0.1 | J8: 0.2 | K8: =H8*I8*J8 | L8: 100 | M8: 0.05 | N8: 0.3 | O8: =L8*M8*N8
D9: 4 | E9: 56 - 60 tahun | H9: 70 | I9: 0.1 | J9: 0.2 | K9: =H9*I9*J9 | L9: 70 | M9: 0.05 | N9: 0.3 | O9: =L9*M9*N9
A10: (b) | B10: Status Perkawinan
D11: 1 | E11: Menikah | H11: 100 | I11: 0.05 | J11: 0.2 | K11: =H11*I11*J11 | L11: 80 | M11: 0.05 | N11: 0.25 | O11: =L11*M11*N11
D12: 2 | E12: Lajang | H12: 80 | I12: 0.05 | J12: 0.2 | K12: =H12*I12*J12 | L12: 100 | M12: 0.05 | N12: 0.25 | O12: =L12*M12*N12 | P12: =K11 | Q12: =K12 | R12: =Q12 | S12: =R12 | T12: lajang | U12: =VLOOKUP('Informasi Pokok'!D22,Parameter!E11:K13,7,0)
E13: Cerai | H13: 80 | I13: 0.05 | J13: 0.2 | K13: =H13*I13*J13
A14: (c) | B14: Jumlah Tanggungan
D15: 1 | E15: > 5 Orang | H15: 25 | I15: 0.05 | J15: 0.35 | K15: =H15*I15*J15 | L15: 25 | M15: 0.05 | N15: 0.45 | O15: =L15*M15*N15
D16: 2 | E16: 3 - 5 Orang | H16: 50 | I16: 0.05 | J16: 0.35 | K16: =H16*I16*J16 | L16: 50 | M16: 0.05 | N16: 0.45 | O16: =L16*M16*N16
D17: 3 | E17: 1 - 2 Orang | H17: 75 | I17: 0.05 | J17: 0.35 | K17: =H17*I17*J17 | L17: 75 | M17: 0.05 | N17: 0.45 | O17: =L17*M17*N17
D18: 4 | E18: Tidak Mempunyai Tanggungan | H18: 100 | I18: 0.05 | J18: 0.35 | K18: =H18*I18*J18 | L18: 100 | M18: 0.05 | N18: 0.45 | O18: =L18*M18*N18 | P18: =K18 | Q18: =K17 | R18: =K16 | S18: =K15 | U18: =VLOOKUP('Informasi Pokok'!$D$23,Parameter!$E$15:$K$18,7,0)
A19: (d) | B19: Tingkat Pendidikan
D20: 1 | E20: SD | H20: 25 | I20: 0.1 | J20: 0.1 | K20: =H20*I20*J20
D21: 2 | E21: SMP | H21: 50 | I21: 0.1 | J21: 0.1 | K21: =H21*I21*J21
D22: 3 | E22: SMA | H22: 75 | I22: 0.1 | J22: 0.1 | K22: =H22*I22*J22
D23: 4 | E23: Dip./S1-S3 | H23: 100 | I23: 0.1 | J23: 0.15 | K23: =H23*I23*J23 | P23: =K23 | Q23: =K22 | R23: =K21 | S23: =K20 | U23: =VLOOKUP('Informasi Pokok'!$D$24,Parameter!E20:K23,7,0)
A25: STEP 2 - INFORMASI TEMPAT TINGGAL
A26: (a) | B26: Kepemilikan tempat tinggal
D27: 1 | E27: Sewa | H27: 25 | I27: 0.1 | J27: 0.4 | K27: =H27*I27*J27 | L27: 25 | M27: 0.1 | N27: 0.6 | O27: =L27*M27*N27
D28: 2 | E28: Lain-lain (Menumpang) | H28: 50 | I28: 0.1 | J28: 0.4 | K28: =H28*I28*J28 | L28: 50 | M28: 0.1 | N28: 0.6 | O28: =L28*M28*N28
D29: 3 | E29: Angsuran | H29: 75 | I29: 0.1 | J29: 0.4 | K29: =H29*I29*J29 | L29: 75 | M29: 0.1 | N29: 0.6 | O29: =L29*M29*N29
D30: 4 | E30: Milik sendiri | H30: 100 | I30: 0.1 | J30: 0.4 | K30: =H30*I30*J30 | L30: 100 | M30: 0.1 | N30: 0.6 | O30: =L30*M30*N30 | P30: =K30 | Q30: =K29 | R30: =K28 | S30: =K27 | U30: =VLOOKUP('Informasi Pokok'!$D$36,Parameter!E27:K30,7,0)
A31: (b) | B31: Lama menetap
D32: 1 | E32: 0 - 2 tahun | H32: 25 | I32: 0.1 | J32: 0.3 | K32: =H32*I32*J32 | L32: 25 | M32: 0.1 | N32: 0.4 | O32: =L32*M32*N32
D33: 2 | E33: > 2 - 5 tahun | H33: 50 | I33: 0.1 | J33: 0.3 | K33: =H33*I33*J33 | L33: 50 | M33: 0.1 | N33: 0.4 | O33: =L33*M33*N33
D34: 3 | E34: > 5 - 8 tahun | H34: 75 | I34: 0.1 | J34: 0.3 | K34: =H34*I34*J34 | L34: 75 | M34: 0.1 | N34: 0.4 | O34: =L34*M34*N34
D35: 4 | E35: > 8 tahun | H35: 100 | I35: 0.1 | J35: 0.3 | K35: =H35*I35*J35 | L35: 100 | M35: 0.1 | N35: 0.4 | O35: =L35*M35*N35 | P35: =K35 | Q35: =K34 | R35: =K33 | S35: =K32 | U35: =VLOOKUP('Informasi Pokok'!$D$37,Parameter!E32:K35,7,0)
A36: (c) | B36: Reputasi di Tempat Tinggal dan Usaha (PG)
D37: 1 | E37: Tidak baik | H37: 0 | I37: 0.1 | J37: 0.3 | K37: =H37*I37*J37
D38: 2 | E38: Tidak dikenal | H38: 20 | I38: 0.1 | J38: 0.3 | K38: =H38*I38*J38
D39: 3 | E39: Dikenal namum kurang bersosialisasi | H39: 75 | I39: 0.1 | J39: 0.3 | K39: =H39*I39*J39
D40: 4 | E40: Dikenal memiliki reputasi baik | H40: 100 | I40: 0.1 | J40: 0.3 | K40: =H40*I40*J40 | P40: =K40 | Q40: =K39 | R40: =K38 | S40: =K37 | U40: =VLOOKUP('Informasi Pokok'!$D$38,Parameter!E37:K40,7,0)
A42: STEP 3 - INFORMASI USAHA
B43: Laporan Keuangan
...

Sheet Rating
B3: HIGH | C3: LOW | D3: RANK | E3: TINGKAT RATING | G3: RANK | H3: PD | I3: PENJELASAN DARI RATING
A4: 1 | B4: 100 | C4: 98 | D4: 1 | E4: AAA | F4: Outstanding | G4: 1 | H4: 0.0003 | I4: Ini adalah rating tertinggi dan terbaik yang diberikan kepada debitur. Kapasitas debitur untuk memenuhi komitmen keuangannya pada pinjaman bank dipandang tidak diragukan.
A5: 2 | B5: 97 | C5: 95 | D5: 2 | E5: AA+ | F5: Strong | G5: 2 | H5: 0.0003 | I5: Debitur yang diberikan rating ‘AA+’ hanya berbeda sedikit dari debitur yang diberikan rating tertinggi (AAA). Kapasitas debitur untuk memenuhi komitmen keuangannya pada pinjamannya sangat baik.
A6: 3 | B6: 94 | C6: 92 | D6: 3 | E6: AA | F6: Strong | G6: 3 | H6: 0.0003 | I6: Debitur yang diberikan rating ‘AA’ hanya berbeda sedikit dari debitur yang diberikan rating tertinggi (AAA). Kapasitas debitur untuk memenuhi komitmen keuangannya pada pinjamannya sangat baik.
A7: 4 | B7: 91 | C7: 89 | D7: 4 | E7: AA- | F7: Strong | G7: 4 | H7: 0.0003 | I7: Debitur yang diberikan rating ‘AA-’ hanya berbeda sedikit dari debitur yang diberikan rating tertinggi (AAA). Kapasitas debitur untuk memenuhi komitmen keuangannya pada pinjamannya sangat baik.
A8: 5 | B8: 88 | C8: 86 | D8: 5 | E8: A+ | F8: Good | G8: 5 | H8: 0.0006 | I8: Debitur yang diberikan rating ‘A+’ agak lebih rentan terhadap keadaan dan kondisi ekonomi yang memburuk dari pada debitur pada rating yang lebih tinggi. Meskipun demikian kapasitas debitur untuk memenuhi komitmen keuangannya pada obligasi masih kuat.
